Workbook

Sheet PBS_corrected
A1: Serum Type | B1: Barcode | C1: IgM_A_HongKong_4801_2014 | D1: IgM_B_Colorado_06_2017 | E1: IgM_B_Phuket_3073_2013 | F1: IgM_A_Brisbane_02_2018 | G1: IgM_A_Wisconsin_67_2022 | H1: IgM_A_Cambodia_e0826360_2020 | I1: IgM_B_Austria_1359417_2021 | J1: IgM_A_Indonesia_05_2005 | K1: IgM_A_Kansas_14_2017 | L1: IgM_A_Victoria_2570_2019 | M1: IgM_A_Shanghai_1_2013 | N1: IgM_A_HongKong_45_2019 | O1: IgM_A_Michigan_45_2015 | P1: IgM_A_California_04_2009 | Q1: IgM_A_Darwin_6_2021 | R1: IgM_Ebola | S1: IgM_EBV | T1: IgM_A_Hawaii_70_2019 | U1: IgM_Michigan_NA | V1: IgM_HongKong_NA | W1: IgM_RSV | X1: IgM_B_Washington_02_2019 | Y1: IgM_A_Wisconsin_588_2019 | Z1: IgM_A_Singapore_INFIMH16_2016 | AA1: IgG1_A_HongKong_4801_2014 | AB1: IgG1_B_Colorado_06_2017 | AC1: IgG1_B_Phuket_3073_2013 | AD1: IgG1_A_Brisbane_02_2018 | AE1: IgG1_A_Wisconsin_67_2022 | AF1: IgG1_A_Cambodia_e0826360_2020 | AG1: IgG1_B_Austria_1359417_2021 | AH1: IgG1_A_Indonesia_05_2005 | AI1: IgG1_A_Kansas_14_2017 | AJ1: IgG1_A_Victoria_2570_2019 | AK1: IgG1_A_Shanghai_1_2013 | AL1: IgG1_A_HongKong_45_2019 | AM1: IgG1_A_Michigan_45_2015 | AN1: IgG1_A_California_04_2009 | AO1: IgG1_A_Darwin_6_2021 | AP1: IgG1_Ebola | AQ1: IgG1_EBV | AR1: IgG1_A_Hawaii_70_2019 | AS1: IgG1_Michigan_NA | AT1: IgG1_HongKong_NA | AU1: IgG1_RSV | AV1: IgG1_B_Washington_02_2019 | AW1: IgG1_A_Wisconsin_588_2019 | AX1: IgG1_A_Singapore_INFIMH16_2016 | AY1: IgG2_A_HongKong_4801_2014 | AZ1: IgG2_B_Colorado_06_2017 | BA1: IgG2_B_Phuket_3073_2013 | BB1: IgG2_A_Brisbane_02_2018 | BC1: IgG2_A_Wisconsin_67_2022 | BD1: IgG2_A_Cambodia_e0826360_2020 | BE1: IgG2_B_Austria_1359417_2021 | BF1: IgG2_A_Indonesia_05_2005 | BG1: IgG2_A_Kansas_14_2017 | BH1: IgG2_A_Victoria_2570_2019 | BI1: IgG2_A_Shanghai_1_2013 | BJ1: IgG2_A_HongKong_45_2019 | BK1: IgG2_A_Michigan_45_2015 | BL1: IgG2_A_California_04_2009 | BM1: IgG2_A_Darwin_6_2021 | BN1: IgG2_Ebola | BO1: IgG2_EBV | BP1: IgG2_A_Hawaii_70_2019 | BQ1: IgG2_Michigan_NA | BR1: IgG2_HongKong_NA | BS1: IgG2_RSV | BT1: IgG2_B_Washington_02_2019 | BU1: IgG2_A_Wisconsin_588_2019 | BV1: IgG2_A_Singapore_INFIMH16_2016 | BW1: IgG3_A_HongKong_4801_2014 | BX1: IgG3_B_Colorado_06_2017 | BY1: IgG3_B_Phuket_3073_2013 | BZ1: IgG3_A_Brisbane_02_2018 | CA1: IgG3_A_Wisconsin_67_2022 | CB1: IgG3_A_Cambodia_e0826360_2020 | CC1: IgG3_B_Austria_1359417_2021 | CD1: IgG3_A_Indonesia_05_2005 | CE1: IgG3_A_Kansas_14_2017 | CF1: IgG3_A_Victoria_2570_2019 | CG1: IgG3_A_Shanghai_1_2013 | CH1: IgG3_A_HongKong_45_2019 | CI1: IgG3_A_Michigan_45_2015 | CJ1: IgG3_A_California_04_2009 | CK1: IgG3_A_Darwin_6_2021 | CL1: IgG3_Ebola | CM1: IgG3_EBV | CN1: IgG3_A_Hawaii_70_2019 | CO1: IgG3_Michigan_NA | CP1: IgG3_HongKong_NA | CQ1: IgG3_RSV | CR1: IgG3_B_Washington_02_2019 | CS1: IgG3_A_Wisconsin_588_2019 | CT1: IgG3_A_Singapore_INFIMH16_2016 | CU1: IgG4_A_HongKong_4801_2014 | CV1: IgG4_B_Colorado_06_2017 | CW1: IgG4_B_Phuket_3073_2013 | CX1: IgG4_A_Brisbane_02_2018 | CY1: IgG4_A_Wisconsin_67_2022 | CZ1: IgG4_A_Cambodia_e0826360_2020 | DA1: IgG4_B_Austria_1359417_2021 | DB1: IgG4_A_Indonesia_05_2005 | DC1: IgG4_A_Kansas_14_2017 | DD1: IgG4_A_Victoria_2570_2019 | DE1: IgG4_A_Shanghai_1_2013 | DF1: IgG4_A_HongKong_45_2019 | DG1: IgG4_A_Michigan_45_2015 | DH1: IgG4_A_California_04_2009 | DI1: IgG4_A_Darwin_6_2021 | DJ1: IgG4_Ebola | DK1: IgG4_EBV | DL1: IgG4_A_Hawaii_70_2019 | DM1: IgG4_Michigan_NA | DN1: IgG4_HongKong_NA | DO1: IgG4_RSV | DP1: IgG4_B_Washington_02_2019 | DQ1: IgG4_A_Wisconsin_588_2019 | DR1: IgG4_A_Singapore_INFIMH16_2016 | DS1: IgA1_A_HongKong_4801_2014 | DT1: IgA1_B_Colorado_06_2017 | DU1: IgA1_B_Phuket_3073_2013 | DV1: IgA1_A_Brisbane_02_2018 | DW1: IgA1_A_Wisconsin_67_2022 | DX1: IgA1_A_Cambodia_e0826360_2020 | DY1: IgA1_B_Austria_1359417_2021 | DZ1: IgA1_A_Indonesia_05_2005 | EA1: IgA1_A_Kansas_14_2017 | EB1: IgA1_A_Victoria_2570_2019 | EC1: IgA1_A_Shanghai_1_2013 | ED1: IgA1_A_HongKong_45_2019 | EE1: IgA1_A_Michigan_45_2015 | EF1: IgA1_A_California_04_2009 | EG1: IgA1_A_Darwin_6_2021 | EH1: IgA1_Ebola | EI1: IgA1_EBV | EJ1: IgA1_A_Hawaii_70_2019 | EK1: IgA1_Michigan_NA | EL1: IgA1_HongKong_NA | EM1: IgA1_RSV | EN1: IgA1_B_Washington_02_2019 | EO1: IgA1_A_Wisconsin_588_2019 | EP1: IgA1_A_Singapore_INFIMH16_2016 | EQ1: IgA2_A_HongKong_4801_2014 | ER1: IgA2_B_Colorado_06_2017 | ES1: IgA2_B_Phuket_3073_2013 | ET1: IgA2_A_Brisbane_02_2018 | EU1: IgA2_A_Wisconsin_67_2022 | EV1: IgA2_A_Singapore_INFIMH16_2016 | EW1: IgA2_A_Cambodia_e0826360_2020 | EX1: IgA2_B_Austria_1359417_2021 | EY1: IgA2_A_Indonesia_05_2005 | EZ1: IgA2_A_Kansas_14_2017 | FA1: IgA2_A_Victoria_2570_2019 | FB1: IgA2_A_Shanghai_1_2013 | FC1: IgA2_A_HongKong_45_2019 | FD1: IgA2_A_Michigan_45_2015 | FE1: IgA2_A_California_04_2009 | FF1: IgA2_A_Darwin_6_2021 | FG1: IgA2_Ebola | FH1: IgA2_EBV | FI1: IgA2_A_Hawaii_70_2019 | FJ1: IgA2_Michigan_NA | FK1: IgA2_HongKong_NA | FL1: IgA2_RSV | FM1: IgA2_B_Washington_02_2019 | FN1: IgA2_A_Wisconsin_588_2019 | FO1: FcgR2A_A_HongKong_4801_2014 | FP1: FcgR2A_B_Colorado_06_2017 | FQ1: FcgR2A_B_Phuket_3073_2013 | FR1: FcgR2A_A_Brisbane_02_2018 | FS1: FcgR2A_A_Wisconsin_67_2022 | FT1: FcgR2A_A_Cambodia_e0826360_2020 | FU1: FcgR2A_B_Austria_1359417_2021 | FV1: FcgR2A_A_Indonesia_05_2005 | FW1: FcgR2A_A_Kansas_14_2017 | FX1: FcgR2A_A_Victoria_2570_2019 | FY1: FcgR2A_A_Shanghai_1_2013 | FZ1: FcgR2A_A_HongKong_45_2019 | GA1: FcgR2A_A_Michigan_45_2015 | GB1: FcgR2A_A_California_04_2009 | GC1: FcgR2A_A_Darwin_6_2021 | GD1: FcgR2A_Ebola | GE1: FcgR2A_EBV | GF1: FcgR2A_A_Hawaii_70_2019 | GG1: FcgR2A_Michigan_NA | GH1: FcgR2A_HongKong_NA | GI1: FcgR2A_RSV | GJ1: FcgR2A_B_Washington_02_2019 | GK1: FcgR2A_A_Wisconsin_588_2019 | GL1: FcgR2A_A_Singapore_INFIMH16_2016 | GM1: FcgR2B_A_HongKong_4801_2014 | GN1: FcgR2B_B_Colorado_06_2017 | GO1: FcgR2B_B_Phuket_3073_2013 | GP1: FcgR2B_A_Brisbane_02_2018 | GQ1: FcgR2B_A_Wisconsin_67_2022 | GR1: FcgR2B_A_Cambodia_e0826360_2020 | GS1: FcgR2B_B_Austria_1359417_2021 | GT1: FcgR2B_A_Indonesia_05_2005 | GU1: FcgR2B_A_Kansas_14_2017 | GV1: FcgR2B_A_Victoria_2570_2019 | GW1: FcgR2B_A_Shanghai_1_2013 | GX1: FcgR2B_A_HongKong_45_2019 | GY1: FcgR2B_A_Michigan_45_2015 | GZ1: FcgR2B_A_California_04_2009 | HA1: FcgR2B_A_Darwin_6_2021 | HB1: FcgR2B_Ebola | HC1: FcgR2B_EBV | HD1: FcgR2B_A_Hawaii_70_2019 | HE1: FcgR2B_Michigan_NA | HF1: FcgR2B_HongKong_NA | HG1: FcgR2B_RSV | HH1: FcgR2B_B_Washington_02_2019 | HI1: FcgR2B_A_Wisconsin_588_2019 | HJ1: FcgR2B_A_Singapore_INFIMH16_2016 | HK1: FcgR3A_A_HongKong_4801_2014 | HL1: FcgR3A_B_Colorado_06_2017 | HM1: FcgR3A_B_Phuket_3073_2013 | HN1: FcgR3A_A_Brisbane_02_2018 | HO1: FcgR3A_A_Wisconsin_67_2022 | HP1: FcgR3A_A_Cambodia_e0826360_2020 | HQ1: FcgR3A_B_Austria_1359417_2021 | HR1: FcgR3A_A_Indonesia_05_2005 | HS1: FcgR3A_A_Kansas_14_2017 | HT1: FcgR3A_A_Victoria_2570_2019 | HU1: FcgR3A_A_Shanghai_1_2013 | HV1: FcgR3A_A_HongKong_45_2019 | HW1: FcgR3A_A_Michigan_45_2015 | HX1: FcgR3A_A_California_04_2009 | HY1: FcgR3A_A_Darwin_6_2021 | HZ1: FcgR3A_Ebola | IA1: FcgR3A_EBV | IB1: FcgR3A_A_Hawaii_70_2019 | IC1: FcgR3A_Michigan_NA | ID1: FcgR3A_HongKong_NA | IE1: FcgR3A_RSV | IF1: FcgR3A_B_Washington_02_2019 | IG1: FcgR3A_A_Wisconsin_588_2019 | IH1: FcgR3A_A_Singapore_INFIMH16_2016 | II1: FcgR3B_A_HongKong_4801_2014 | IJ1: FcgR3B_B_Colorado_06_2017 | IK1: FcgR3B_B_Phuket_3073_2013 | IL1: FcgR3B_A_Brisbane_02_2018 | IM1: FcgR3B_A_Wisconsin_67_2022 | IN1: FcgR3B_A_Cambodia_e0826360_2020 | IO1: FcgR3B_B_Austria_1359417_2021 | IP1: FcgR3B_A_Indonesia_05_2005 | IQ1: FcgR3B_A_Kansas_14_2017 | IR1: FcgR3B_A_Victoria_2570_2019 | IS1: FcgR3B_A_Shanghai_1_2013 | IT1: FcgR3B_A_HongKong_45_2019 | IU1: FcgR3B_A_Michigan_45_2015 | IV1: FcgR3B_A_California_04_2009 | IW1: FcgR3B_A_Darwin_6_2021 | IX1: FcgR3B_Ebola | IY1: FcgR3B_EBV | IZ1: FcgR3B_A_Hawaii_70_2019 | JA1: FcgR3B_Michigan_NA | JB1: FcgR3B_HongKong_NA | JC1: FcgR3B_RSV | JD1: FcgR3B_B_Washington_02_2019 | JE1: FcgR3B_A_Wisconsin_588_2019 | JF1: FcgR3B_A_Singapore_INFIMH16_2016 | JG1: ADCD_A_Michigan_45_2015 | JH1: ADCD_A_California_04_2009 | JI1: ADCD_A_HongKong_4801_2014 | JJ1: ADCD_B_Phuket_3073_2013 | JK1: ADCD_A_Singapore_INFIMH16_2016 | JL1: ADCD_B_Colorado_06_2017 | JM1: ADCD_B_Washington_02_2019 | JN1: ADCD_A_Kansas_14_2017 | JO1: ADCD_A_Wisconsin_67_2022 | JP1: ADCD_A_Victoria_2570_2019 | JQ1: ADCD_A_Cambodia_e0826360_2020 | JR1: ADCD_A_Shanghai_1_2013 | JS1: ADCD_A_Indonesia_05_2005 | JT1: ADCD_Ebola | JU1: ADCD_A_HongKong_45_2019 | JV1: ADCD_A_Wisconsin_588_2019 | JW1: ADCD_A_Brisbane_02_2018 | JX1: ADCD_B_Austria_1359417_2021 | JY1: ADCD_A_Darwin_6_2021 | JZ1: ADCD_RSV | KA1: ADCD_EBV | KB1: ADCD_A_Hawaii_70_2019 | KC1: ADCD_Michigan NA | KD1: ADCD_HongKong NA
A2: Mother | B2: 221417 | C2: 81835.58 | D2: 18301.466 | E2: 151688.89 | F2: 25469.943 | G2: 9550.8295 | H2: 5909.6591 | I2: 15414.148 | J2: 4251.4432 | K2: 38958.852 | L2: 64696.602 | M2: 6361.7159 | N2: 7002.2955 | O2: 38310.58 | P2: 48244.205 | Q2: 15528.943 | R2: 54569.25 | S2: 57505.943 | T2: 17574.693 | U2: 9589.5568 | V2: 6133.2159 | W2: 42611.5 | X2: 15546.75 | Y2: 81467.75 | Z2: 13021.864 | AA2: 909570.91 | AB2: 99634.438 | AC2: 560701 | AD2: 203058.7 | AE2: 268682.53 | AF2: 479549.86 | AG2: 274597.81 | AH2: 17673.55 | AI2: 520966.3 | AJ2: 222150.21 | AK2: 9020.6125 | AL2: 596668.49 | AM2: 338311.99 | AN2: 846693.39 | AO2: 473409.53 | AP2: 1130.9625 | AQ2: 35098.425 | AR2: 520804.71 | AS2: 2897.9625 | AT2: 184239.94 | AU2: 1174888.4 | AV2: 41621.213 | AW2: 251585.02 | AX2: 491786.3 | AY2: 12525.2 | AZ2: 1690.0625 | BA2: 36726.213 | BB2: 2121.6625 | BC2: 3771.425 | BD2: 2432.95 | BE2: 2950.775 | BF2: 280.3125 | BG2: 16213.8 | BH2: 2436.1 | BI2: 896.725 | BJ2: 3874.5125 | BK2: 3419.9875 | BL2: 9852.8 | BM2: 1736.5375 | BN2: 1524.825 | BO2: 1266.775 | BP2: 4811.55 | BQ2: 1089.1125 | BR2: 780.6375 | BS2: 22160.638 | BT2: 1480.9125 | BU2: 3600.35 | BV2: 4424.2875 | BW2: 4874.4091 | BX2: 4560.5682 | BY2: 22670.08 | BZ2: 1489.7727 | CA2: 3317.1023 | CB2: 2670.0682 | CC2: 4620.0227 | CD2: 297.15909 | CE2: 7508.0114 | CF2: 1918.1818 | CG2: 19709.364 | CH2: 2908.8977 | CI2: 2069.6932 | CJ2: 3395.5795 | CK2: 4577.1932 | CL2: 362.17045 | CM2: 1881.3977 | CN2: 2311.3409 | CO2: 360.04545 | CP2: 3661.4659 | CQ2: 212810.7 | CR2: 2606.4659 | CS2: 2595.3977 | CT2: 3431.0568 | CU2: 204.35 | CV2: 882.85 | CW2: 286.7125 | CX2: 39.6625 | CY2: 557.6 | CZ2: 166.525 | DA2: 1234.725 | DB2: 108.2125 | DC2: 173.9125 | DD2: 253.175 | DE2: 58.65 | DF2: 215.7875 | DG2: 59.6 | DH2: 454.1625 | DI2: 387.475 | DJ2: 273.8125 | DK2: 40.85 | DL2: 351.1625 | DM2: 333.05 | DN2: 157 | DO2: 0 | DP2: 1343.05 | DQ2: 208.625 | DR2: 224.1125 | DS2: 76917.42 | DT2: 28567.273 | DU2: 125179.62 | DV2: 27756.909 | DW2: 9759.8295 | DX2: 26341.284 | DY2: 51769.455 | DZ2: 4263.9091 | EA2: 60524.909 | EB2: 9290.0909 | EC2: 5060.375 | ED2: 56698.216 | EE2: 33670.42 | EF2: 52851.091 | EG2: 30497.318 | EH2: 6264.5682 | EI2: 19293.955 | EJ2: 34180.898 | EK2: 4008.8977 | EL2: 5739.0682 | EM2: 1293679.6 | EN2: 27847.045 | EO2: 10494.136 | EP2: 45341.114 | EQ2: 816.94231 | ER2: 278.05769 | ES2: 1875.8173 | ET2: 314.89423 | EU2: 201 | EV2: 235.45192 | EW2: 214.16346 | EX2: 82.836538 | EY2: 57.067308 | EZ2: 1207.8462 | FA2: 139.13462 | FB2: 0 | FC2: 334.94231 | FD2: 210.89423 | FE2: 749.78846 | FF2: 256.31731 | FG2: 749.42308 | FH2: 152.39423 | FI2: 504.47115 | FJ2: 158.94231 | FK2: 77.346154 | FL2: 3047.4038 | FM2: 220.19231 | FN2: 165.63462 | FO2: =IF((Pasted_data!C2-Pasted_data!C$148)<0,0,Pasted_data!C2-Pasted_data!C$148) -> 875883.62 | FP2: =IF((Pasted_data!D2-Pasted_data!D$148)<0,0,Pasted_data!D2-Pasted_data!D$148) -> 323716.67 | FQ2: =IF((Pasted_data!E2-Pasted_data!E$148)<0,0,Pasted_data!E2-Pasted_data!E$148) -> 262780.14 | FR2: =IF((Pasted_data!F2-Pasted_data!F$148)<0,0,Pasted_data!F2-Pasted_data!F$148) -> 358373.73 | FS2: =IF((Pasted_data!G2-Pasted_data!G$148)<0,0,Pasted_data!G2-Pasted_data!G$148) -> 824087.77 | FT2: =IF((Pasted_data!H2-Pasted_data!H$148)<0,0,Pasted_data!H2-Pasted_data!H$148) -> 758783.11 | FU2: =IF((Pasted_data!I2-Pasted_data!I$148)<0,0,Pasted_data!I2-Pasted_data!I$148) -> 602827.73 | FV2: =IF((Pasted_data!J2-Pasted_data!J$148)<0,0,Pasted_data!J2-Pasted_data!J$148) -> 272204.32 | ... JF2: =IF((Pasted_data!CT2-Pasted_data!CT$148)<0,0,Pasted_data!CT2-Pasted_data!CT$148) -> 1266176.2 | JG2: 378688.79 | JH2: 972163.92 | JI2: 990353.96 | JJ2: 723714.14 | JK2: 672217.5 | JL2: 29385.75 | JM2: 17859.779 | JN2: 1004216.4 | JO2: 565786.54 | JP2: 356999.01 | JQ2: 509372.63 | JR2: 23765.346 | JS2: 13718.462 | JT2: 47361.173 | JU2: 752502.97 | JV2: 310659.9 | JW2: 72183.933 | JX2: 28884.135 | JY2: 499413.91 | JZ2: 61834.721 | KA2: 21140 | KB2: 815030.96 | KC2: 46335.24 | KD2: 352881.88
A3: Mother | B3: 221432 | C3: 45941.5 | D3: 7221.5385 | E3: 159940.38 | F3: 26576.712 | G3: 4748.5 | H3: 3251.4231 | I3: 12785.173 | J3: 2003.9615 | K3: 81276.346 | L3: 66446.75 | M3: 3922.3077 | N3: 44381.365 | O3: 38331.231 | P3: 70160.846 | Q3: 2969.4423 | R3: 23777.173 | S3: 26610.962 | T3: 17980.231 | U3: 10626.981 | V3: 6458.4615 | W3: 22785.231 | X3: 6796.0385 | Y3: 64117.846 | Z3: 15050.577 | AA3: 44097.615 | AB3: 7576.2115 | AC3: 13318.404 | AD3: 6980.7885 | AE3: 3793.7308 | AF3: 1752.6923 | AG3: 58475.288 | AH3: 0 | AI3: 68405.635 | AJ3: 9189.9038 | AK3: 0 | AL3: 72224.788 | AM3: 18952.462 | AN3: 56248.923 | AO3: 1283.7885 | AP3: 693.32692 | AQ3: 29.711538 | AR3: 18027.269 | AS3: 426.69231 | AT3: 28555.962 | AU3: 891.26923 | AV3: 5792.8269 | AW3: 17579.75 | AX3: 13591.962 | AY3: 55735.385 | AZ3: 1754.5962 | BA3: 15286.096 | BB3: 1573.4808 | BC3: 1275.8462 | BD3: 1476.2885 | BE3: 4491.6731 | BF3: 338.73077 | BG3: 13503.25 | BH3: 4446.4038 | BI3: 413.01923 | BJ3: 36218.808 | BK3: 4044.0577 | BL3: 20809.038 | BM3: 396.38462 | BN3: 1520.2115 | BO3: 826.48077 | BP3: 2643.5 | BQ3: 204.48077 | BR3: 777.17308 | BS3: 2146.7308 | BT3: 1614.6538 | BU3: 4002.4231 | BV3: 6635 | BW3: 6834.9038 | BX3: 9767.0577 | BY3: 30782.635 | BZ3: 2154.1923 | CA3: 5754.5192 | CB3: 2341.5577 | CC3: 20495.846 | CD3: 108.32692 | CE3: 8382.9231 | CF3: 3510.6731 | CG3: 652.17308 | CH3: 5440.6346 | CI3: 2911.0769 | CJ3: 6472.9038 | CK3: 3896.3846 | CL3: 618.65385 | CM3: 736.63462 | CN3: 4036.5769 | CO3: 681.76923 | CP3: 686.92308 | CQ3: 2088.7692 | CR3: 7753.0192 | CS3: 4231.0192 | CT3: 3567.8654 | CU3: 23070.538 | CV3: 39676.269 | CW3: 20648.019 | CX3: 36330.346 | CY3: 70118.692 | CZ3: 8351.9808 | DA3: 40948.596 | DB3: 212.80769 | DC3: 7343.2308 | DD3: 59288.519 | DE3: 15384.712 | DF3: 19329.346 | DG3: 89786.135 | DH3: 189773.35 | DI3: 1623.0962 | DJ3: 303.01923 | DK3: 150.44231 | DL3: 35562.308 | DM3: 0 | DN3: 595.42308 | DO3: 2075.4423 | DP3: 44565.673 | DQ3: 57644.538 | DR3: 14631.5 | DS3: 4876.3077 | DT3: 1927.1346 | DU3: 18400.673 | DV3: 14046.423 | DW3: 2595.8654 | DX3: 2760.25 | DY3: 3763.6154 | DZ3: 144.63462 | EA3: 8267.6154 | EB3: 5218.7308 | EC3: 823.51923 | ED3: 4096.0577 | EE3: 23360.808 | EF3: 35222.462 | EG3: 2468.5769 | EH3: 1017.9423 | EI3: 755.94231 | EJ3: 10208.346 | EK3: 3817.1731 | EL3: 852.15385 | EM3: 2471.5769 | EN3: 3992.4423 | EO3: 5875.0577 | EP3: 1533.0962 | EQ3: 60.192308 | ER3: 61.807692 | ES3: 584.56731 | ET3: 259.39423 | EU3: 9.5 | EV3: 102.20192 | EW3: 145.16346 | EX3: 17.336538 | EY3: 0 | EZ3: 200.59615 | FA3: 0 | FB3: 160.29808 | FC3: 17.692308 | FD3: 274.64423 | FE3: 439.28846 | FF3: 88.317308 | FG3: 213.92308 | FH3: 0 | FI3: 183.47115 | FJ3: 0 | FK3: 19.096154 | FL3: 0 | FM3: 38.192308 | FN3: 82.634615 | FO3: =IF((Pasted_data!C74-Pasted_data!C$148)<0,0,Pasted_data!C74-Pasted_data!C$148) -> 853058.38 | FP3: =IF((Pasted_data!D74-Pasted_data!D$148)<0,0,Pasted_data!D74-Pasted_data!D$148) -> 511923.92 | FQ3: =IF((Pasted_data!E74-Pasted_data!E$148)<0,0,Pasted_data!E74-Pasted_data!E$148) -> 147971.64 | FR3: =IF((Pasted_data!F74-Pasted_data!F$148)<0,0,Pasted_data!F74-Pasted_data!F$148) -> 412892.73 | FS3: =IF((Pasted_data!G74-Pasted_data!G$148)<0,0,Pasted_data!G74-Pasted_data!G$148) -> 519656.77 | FT3: =IF((Pasted_data!H74-Pasted_data!H$148)<0,0,Pasted_data!H74-Pasted_data!H$148) -> 509297.11 | FU3: =IF((Pasted_data!I74-Pasted_data!I$148)<0,0,Pasted_data!I74-Pasted_data!I$148) -> 706686.73 | FV3: =IF((Pasted_data!J74-Pasted_data!J$148)<0,0,Pasted_data!J74-Pasted_data!J$148) -> 12529.067 | ... JF3: =IF((Pasted_data!CT74-Pasted_data!CT$148)<0,0,Pasted_data!CT74-Pasted_data!CT$148) -> 467349.92 | JG3: 464164.54 | JH3: 910743.42 | JI3: 852577.96 | JJ3: 740852.89 | JK3: 527376.75 | JL3: 693649.25 | JM3: 589172.28 | JN3: 892958.38 | JO3: 686365.29 | JP3: 844677.76 | JQ3: 389949.38 | JR3: 14730.346 | JS3: 7754.7115 | JT3: 11169.423 | JU3: 920969.72 | JV3: 887944.9 | JW3: 143263.93 | JX3: 718553.13 | JY3: 0 | JZ3: 17362.471 | KA3: 21067 | KB3: 832757.96 | KC3: 42154.49 | KD3: 761511.13
A4: Mother | B4: 222567 | C4: 61204.08 | D4: 66102.966 | E4: 204959.14 | F4: 11584.693 | G4: 35392.08 | H4: 12082.409 | I4: 195053.9 | J4: 1868.9432 | K4: 51208.852 | L4: 35247.602 | M4: 9142.7159 | N4: 12235.795 | O4: 18772.83 | P4: 76640.205 | Q4: 12612.943 | R4: 35571 | S4: 20503.693 | T4: 54211.943 | U4: 2946.0568 | V4: 6506.2159 | W4: 82211 | X4: 212938.25 | Y4: 46754 | Z4: 7200.1136 | AA4: 27981.162 | AB4: 25033.438 | AC4: 35054 | AD4: 21494.7 | AE4: 72340.025 | AF4: 9950.8625 | AG4: 30218.062 | AH4: 305.55 | AI4: 71822.05 | AJ4: 74306.962 | AK4: 222.1125 | AL4: 17500.487 | AM4: 34637.738 | AN4: 153752.64 | AO4: 17521.275 | AP4: 42.4625 | AQ4: 2204.425 | AR4: 92411.962 | AS4: 382.4625 | AT4: 2823.9375 | AU4: 56508.662 | AV4: 24586.213 | AW4: 101974.52 | AX4: 25101.8 | AY4: 9437.7 | AZ4: 4363.5625 | BA4: 8446.7125 | BB4: 1378.1625 | BC4: 3380.925 | BD4: 6164.2 | BE4: 3715.275 | BF4: 458.5625 | BG4: 11413.55 | BH4: 2388.6 | BI4: 239.475 | BJ4: 37973.012 | BK4: 2074.9875 | BL4: 5150.55 | BM4: 3541.5375 | BN4: 1423.325 | BO4: 743.275 | BP4: 3939.05 | BQ4: 130.3625 | BR4: 1307.8875 | BS4: 48179.637 | BT4: 3754.1625 | BU4: 3218.6 | BV4: 1646.0375 | BW4: 205149.41 | BX4: 44586.318 | BY4: 136979.08 | BZ4: 79035.523 | CA4: 202809.6 | CB4: 187871.07 | CC4: 47063.023 | CD4: 32441.159 | CE4: 193212.26 | CF4: 136671.93 | CG4: 1723.3636 | CH4: 226747.4 | CI4: 114304.94 | CJ4: 169628.08 | CK4: 225915.44 | CL4: 622.92045 | CM4: 2100.8977 | CN4: 157714.34 | CO4: 202.29545 | CP4: 8792.9659 | CQ4: 12138.705 | CR4: 46410.216 | CS4: 158540.9 | CT4: 255415.31 | CU4: 766.85 | CV4: 928.1 | CW4: 1859.7125 | CX4: 306.1625 | CY4: 815.85 | CZ4: 635.025 | DA4: 825.975 | DB4: 104.7125 | DC4: 1109.4125 | DD4: 649.675 | DE4: 267.15 | DF4: 794.5375 | DG4: 535.6 | DH4: 1245.1625 | DI4: 821.475 | DJ4: 257.3125 | DK4: 332.85 | DL4: 889.4125 | DM4: 0 | DN4: 416 | DO4: 406.225 | DP4: 626.8 | DQ4: 734.625 | DR4: 302.3625 | DS4: 159912.67 | DT4: 209875.02 | DU4: 559380.62 | DV4: 88099.909 | DW4: 265411.58 | DX4: 192494.03 | DY4: 199441.45 | DZ4: 14228.159 | EA4: 225402.66 | EB4: 168725.34 | EC4: 4268.125 | ED4: 320678.47 | EE4: 118446.92 | EF4: 149380.59 | EG4: 201211.82 | EH4: 7459.5682 | EI4: 6409.4545 | EJ4: 159093.65 | EK4: 1603.8977 | EL4: 1421.8182 | EM4: 199669.64 | EN4: 229240.05 | EO4: 201557.89 | EP4: 143712.61 | EQ4: 2588.6923 | ER4: 2343.8077 | ES4: 36463.067 | ET4: 538.64423 | EU4: 3813.25 | EV4: 251.70192 | EW4: 3601.4135 | EX4: 717.83654 | EY4: 67.817308 | EZ4: 5067.3462 | FA4: 2053.8846 | FB4: 64.298077 | FC4: 9959.1923 | FD4: 882.39423 | FE4: 1282.5385 | FF4: 5207.8173 | FG4: 388.17308 | FH4: 152.14423 | FI4: 1531.7212 | FJ4: 124.19231 | FK4: 265.84615 | FL4: 143.40385 | FM4: 2360.6923 | FN4: 2395.6346 | FO4: =IF((Pasted_data!C3-Pasted_data!C$148)<0,0,Pasted_data!C3-Pasted_data!C$148) -> 796344.38 | FP4: =IF((Pasted_data!D3-Pasted_data!D$148)<0,0,Pasted_data!D3-Pasted_data!D$148) -> 552395.17 | FQ4: =IF((Pasted_data!E3-Pasted_data!E$148)<0,0,Pasted_data!E3-Pasted_data!E$148) -> 269867.89 | FR4: =IF((Pasted_data!F3-Pasted_data!F$148)<0,0,Pasted_data!F3-Pasted_data!F$148) -> 576043.23 | FS4: =IF((Pasted_data!G3-Pasted_data!G$148)<0,0,Pasted_data!G3-Pasted_data!G$148) -> 703148.77 | FT4: =IF((Pasted_data!H3-Pasted_data!H$148)<0,0,Pasted_data!H3-Pasted_data!H$148) -> 620866.11 | FU4: =IF((Pasted_data!I3-Pasted_data!I$148)<0,0,Pasted_data!I3-Pasted_data!I$148) -> 716090.98 | FV4: =IF((Pasted_data!J3-Pasted_data!J$148)<0,0,Pasted_data!J3-Pasted_data!J$148) -> 200889.07 | ... JF4: =IF((Pasted_data!CT3-Pasted_data!CT$148)<0,0,Pasted_data!CT3-Pasted_data!CT$148) -> 1253046.4 | JG4: 953082.54 | JH4: 1055476.9 | JI4: 922248.46 | JJ4: 999040.89 | JK4: 733981.25 | JL4: 932096 | JM4: 967146.28 | JN4: 1030235.6 | JO4: 1040553.8 | JP4: 1022188.3 | JQ4: 823395.13 | JR4: 46591.096 | JS4: 37141.962 | JT4: 116051.17 | JU4: 965649.47 | JV4: 1048855.4 | JW4: 793483.18 | JX4: 966761.63 | JY4: 508964.91 | JZ4: 218215.72 | KA4: 48552.75 | KB4: 987830.96 | KC4: 77704.49 | KD4: 315410.88
A5: Mother | B5: 224423 | C5: 58188.33 | D5: 14250.466 | E5: 175767.14 | F5: 2967.9432 | G5: 3721.3295 | H5: 3865.6591 | I5: 16039.648 | J5: 3735.4432 | K5: 31451.102 | L5: 3940.8523 | M5: 18118.216 | N5: 8550.5455 | O5: 11880.58 | P5: 5241.7045 | Q5: 15811.443 | R5: 44916.5 | S5: 72918.943 | T5: 4955.1932 | U5: 10046.807 | V5: 8043.7159 | W5: 322550.5 | X5: 11477.75 | Y5: 5420.25 | Z5: 2714.6136 | AA5: 536309.41 | AB5: 134257.44 | AC5: 341088.25 | AD5: 28411.95 | AE5: 32568.525 | AF5: 138000.36 | AG5: 228590.06 | AH5: 4481.3 | AI5: 294999.05 | AJ5: 34962.963 | AK5: 11018.362 | AL5: 345219.99 | AM5: 71012.488 | AN5: 97555.387 | AO5: 182559.77 | AP5: 596.9625 | AQ5: 23556.425 | AR5: 27016.463 | AS5: 698.2125 | AT5: 22912.438 | AU5: 3342224.2 | AV5: 90116.962 | AW5: 38439.025 | AX5: 167090.3 | AY5: 5203.7 | AZ5: 449.5625 | BA5: 10042.212 | BB5: 230.9125 | BC5: 138.925 | BD5: 844.45 | BE5: 2091.775 | BF5: 65.8125 | BG5: 3766.3 | BH5: 191.1 | BI5: 157.725 | BJ5: 630.0125 | BK5: 379.2375 | BL5: 466.3 | BM5: 309.7875 | BN5: 82.075 | BO5: 531.775 | BP5: 230.05 | BQ5: 506.6125 | BR5: 0 | BS5: 39260.637 | BT5: 711.4125 | BU5: 0 | BV5: 592.7875 | BW5: 7740.9091 | BX5: 820.81818 | BY5: 17059.08 | BZ5: 3023.0227 | CA5: 1247.6023 | CB5: 2804.3182 | CC5: 4914.2727 | CD5: 373.15909 | CE5: 7972.7614 | CF5: 2204.9318 | CG5: 212.36364 | CH5: 3139.8977 | CI5: 1838.1932 | CJ5: 2111.3295 | CK5: 9987.6932 | CL5: 224.92045 | CM5: 562.89773 | CN5: 1318.3409 | CO5: 294.04545 | CP5: 281.96591 | CQ5: 189225.45 | CR5: 1186.9659 | CS5: 2117.8977 | CT5: 3770.3068 | CU5: 440.6 | CV5: 38.1 | CW5: 1129.2125 | CX5: 140.1625 | CY5: 89.35 | CZ5: 253.525 | DA5: 313.475 | DB5: 3.4625 | DC5: 470.1625 | DD5: 161.175 | DE5: 181.9 | DF5: 70.5375 | DG5: 92.1 | DH5: 257.6625 | DI5: 320.475 | DJ5: 294.8125 | DK5: 219.6 | DL5: 71.9125 | DM5: 0 | DN5: 0 | DO5: 1669.725 | DP5: 256.8 | DQ5: 0 | DR5: 77.6125 | DS5: 45978.17 | DT5: 3081.0227 | DU5: 25764.125 | DV5: 2320.6591 | DW5: 8573.8295 | DX5: 15639.034 | DY5: 9505.4545 | DZ5: 621.65909 | EA5: 55264.409 | EB5: 5011.8409 | EC5: 1468.375 | ED5: 27886.466 | EE5: 5090.1705 | EF5: 9864.8409 | EG5: 3895.5682 | EH5: 270.81818 | EI5: 7581.7045 | EJ5: 1955.3977 | EK5: 686.89773 | EL5: 788.81818 | EM5: 276262.89 | EN5: 2274.2955 | EO5: 6075.1364 | EP5: 11187.614 | EQ5: 260.69231 | ER5: 249.05769 | ES5: 501.56731 | ET5: 146.89423 | EU5: 122 | EV5: 35.951923 | EW5: 186.41346 | EX5: 15.836538 | EY5: 7.5673077 | EZ5: 655.59615 | FA5: 108.88462 | FB5: 224.54808 | FC5: 96.442308 | FD5: 222.89423 | FE5: 207.03846 | FF5: 58.317308 | FG5: 459.42308 | FH5: 307.89423 | FI5: 84.721154 | FJ5: 0 | FK5: 188.59615 | FL5: 723.65385 | FM5: 128.69231 | FN5: 43.384615 | FO5: =IF((Pasted_data!C4-Pasted_data!C$148)<0,0,Pasted_data!C4-Pasted_data!C$148) -> 1123423.4 | FP5: =IF((Pasted_data!D4-Pasted_data!D$148)<0,0,Pasted_data!D4-Pasted_data!D$148) -> 587624.42 | FQ5: =IF((Pasted_data!E4-Pasted_data!E$148)<0,0,Pasted_data!E4-Pasted_data!E$148) -> 420851.89 | FR5: =IF((Pasted_data!F4-Pasted_data!F$148)<0,0,Pasted_data!F4-Pasted_data!F$148) -> 105466.48 | FS5: =IF((Pasted_data!G4-Pasted_data!G$148)<0,0,Pasted_data!G4-Pasted_data!G$148) -> 162325.02 | FT5: =IF((Pasted_data!H4-Pasted_data!H$148)<0,0,Pasted_data!H4-Pasted_data!H$148) -> 506043.11 | FU5: =IF((Pasted_data!I4-Pasted_data!I$148)<0,0,Pasted_data!I4-Pasted_data!I$148) -> 806281.23 | FV5: =IF((Pasted_data!J4-Pasted_data!J$148)<0,0,Pasted_data!J4-Pasted_data!J$148) -> 26321.817 | ... JF5: =IF((Pasted_data!CT4-Pasted_data!CT$148)<0,0,Pasted_data!CT4-Pasted_data!CT$148) -> 618703.92 | JG5: 13915.538 | JH5: 31317.923 | JI5: 884137.46 | JJ5: 281554.14 | JK5: 99195 | JL5: 77494.25 | JM5: 39658.779 | JN5: 164672.13 | JO5: 18487.288 | JP5: 22902.51 | JQ5: 28022.885 | JR5: 15554.596 | JS5: 5161.2115 | JT5: 39276.173 | JU5: 404746.97 | JV5: 8027.1538 | JW5: 11517.433 | JX5: 29421.635 | JY5: 200001.16 | JZ5: 488928.97 | KA5: 16089.75 | KB5: 6187.4615 | KC5: 59843.74 | KD5: 45424.135
A6: Mother | B6: 224442 | C6: 34760.75 | D6: 1389.7885 | E6: 79063.885 | F6: 1575.4615 | G6: 1020 | H6: 31022.173 | I6: 9820.4231 | J6: 549.46154 | K6: 39840.346 | L6: 1132.5 | M6: 1175.3077 | N6: 13874.865 | O6: 1137.7308 | P6: 2843.5962 | Q6: 34143.442 | R6: 6181.6731 | S6: 13593.212 | T6: 1076.4808 | U6: 4433.9808 | V6: 650.21154 | W6: 6378.2308 | X6: 24616.788 | Y6: 1060.8462 | Z6: 2351.8269 | AA6: 7.8653846 | AB6: 2506.2115 | AC6: 9394.1538 | AD6: 0 | AE6: 0 | AF6: 28.192308 | AG6: 51846.788 | AH6: 0 | AI6: 0 | AJ6: 0 | AK6: 0 | AL6: 239.78846 | AM6: 3434.9615 | AN6: 9501.4231 | AO6: 186.53846 | AP6: 464.57692 | AQ6: 21.711538 | AR6: 0 | AS6: 0 | AT6: 2257.9615 | AU6: 2100.0192 | AV6: 565.57692 | AW6: 0 | AX6: 91.961538 | AY6: 6125.8846 | AZ6: 58.846154 | BA6: 6596.5962 | BB6: 107.98077 | BC6: 314.84615 | BD6: 278.03846 | BE6: 2483.6731 | BF6: 113.98077 | BG6: 1782.75 | BH6: 192.40385 | BI6: 89.769231 | BJ6: 287.30769 | BK6: 141.05769 | BL6: 394.28846 | BM6: 321.88462 | BN6: 1179.7115 | BO6: 348.48077 | BP6: 358 | BQ6: 0 | BR6: 292.92308 | BS6: 2147.9808 | BT6: 310.40385 | BU6: 178.92308 | BV6: 184 | BW6: 12784.904 | BX6: 3184.3077 | BY6: 21062.635 | BZ6: 5054.4423 | CA6: 3567.5192 | CB6: 590.55769 | CC6: 10266.596 | CD6: 626.32692 | CE6: 6756.1731 | CF6: 4143.4231 | CG6: 1406.9231 | CH6: 898.63462 | CI6: 4360.5769 | CJ6: 7569.1538 | CK6: 1159.6346 | CL6: 2571.6538 | CM6: 782.63462 | CN6: 3411.0769 | CO6: 73.519231 | CP6: 144.67308 | CQ6: 2872.0192 | CR6: 3147.5192 | CS6: 5470.2692 | CT6: 1154.6154 | CU6: 485.28846 | CV6: 81.019231 | CW6: 61.769231 | CX6: 251.84615 | CY6: 213.19231 | CZ6: 186.98077 | DA6: 82.846154 | DB6: 0 | DC6: 17.980769 | DD6: 79.019231 | DE6: 256.46154 | DF6: 0 | DG6: 125.88462 | DH6: 666.84615 | DI6: 199.09615 | DJ6: 185.76923 | DK6: 0 | DL6: 0 | DM6: 0 | DN6: 0 | DO6: 0 | DP6: 0 | DQ6: 269.28846 | DR6: 0 | DS6: 7116.8077 | DT6: 1779.3846 | DU6: 25183.173 | DV6: 755.42308 | DW6: 2189.1154 | DX6: 3607.75 | DY6: 2699.8654 | DZ6: 269.13462 | EA6: 21553.365 | EB6: 1622.7308 | EC6: 179.76923 | ED6: 5280.5577 | EE6: 2270.0577 | EF6: 5311.4615 | EG6: 2903.5769 | EH6: 715.69231 | EI6: 11718.192 | EJ6: 1642.5962 | EK6: 0 | EL6: 223.40385 | EM6: 2692.3269 | EN6: 6344.9423 | EO6: 1961.8077 | EP6: 658.09615 | EQ6: 62.442308 | ER6: 28.557692 | ES6: 515.56731 | ET6: 100.14423 | EU6: 44 | EV6: 16.951923 | EW6: 67.163462 | EX6: 191.83654 | EY6: 0 | EZ6: 575.59615 | FA6: 80.634615 | FB6: 64.548077 | FC6: 117.19231 | FD6: 124.89423 | FE6: 59.288462 | FF6: 71.067308 | FG6: 0 | FH6: 201.89423 | FI6: 36.221154 | FJ6: 0 | FK6: 0 | FL6: 0 | FM6: 105.19231 | FN6: 1.3846154 | FO6: =IF((Pasted_data!C53-Pasted_data!C$148)<0,0,Pasted_data!C53-Pasted_data!C$148) -> 609401.62 | FP6: =IF((Pasted_data!D53-Pasted_data!D$148)<0,0,Pasted_data!D53-Pasted_data!D$148) -> 717203.42 | FQ6: =IF((Pasted_data!E53-Pasted_data!E$148)<0,0,Pasted_data!E53-Pasted_data!E$148) -> 365114.14 | FR6: =IF((Pasted_data!F53-Pasted_data!F$148)<0,0,Pasted_data!F53-Pasted_data!F$148) -> 582154.73 | FS6: =IF((Pasted_data!G53-Pasted_data!G$148)<0,0,Pasted_data!G53-Pasted_data!G$148) -> 876831.52 | FT6: =IF((Pasted_data!H53-Pasted_data!H$148)<0,0,Pasted_data!H53-Pasted_data!H$148) -> 303155.11 | FU6: =IF((Pasted_data!I53-Pasted_data!I$148)<0,0,Pasted_data!I53-Pasted_data!I$148) -> 1050333 | FV6: =IF((Pasted_data!J53-Pasted_data!J$148)<0,0,Pasted_data!J53-Pasted_data!J$148) -> 197686.57 | ... JF6: =IF((Pasted_data!CT53-Pasted_data!CT$148)<0,0,Pasted_data!CT53-Pasted_data!CT$148) -> 168329.42 | JG6: 377081.04 | JH6: 926620.67 | JI6: 83577.962 | JJ6: 680784.14 | JK6: 7429.25 | JL6: 250698 | JM6: 69294.029 | JN6: 11523.885 | JO6: 480485.54 | JP6: 526011.01 | JQ6: 9639.3846 | JR6: 12657.346 | JS6: 6929.9615 | JT6: 22511.673 | JU6: 26875.971 | JV6: 428182.15 | JW6: 77825.683 | JX6: 220054.13 | JY6: 62130.413 | JZ6: 25516.471 | KA6: 14669.25 | KB6: 174371.46 | KC6: 16856.74 | KD6: 20658.885
A7: Mother | B7: 224467 | C7: 40500.08 | D7: 9946.4659 | E7: 199870.64 | F7: 4808.6932 | G7: 1761.3295 | H7: 11425.409 | I7: 44318.398 | J7: 979.44318 | K7: 55597.352 | L7: 6823.6023 | M7: 1594.9659 | N7: 5604.7955 | O7: 8702.0795 | P7: 21716.205 | Q7: 17250.693 | R7: 2847 | S7: 10101.443 | T7: 4467.9432 | U7: 2181.5568 | V7: 1609.7159 | W7: 158845 | X7: 86010.75 | Y7: 7301.5 | Z7: 7330.8636 | AA7: 632148.41 | AB7: 759246.69 | AC7: 1814054 | AD7: 365298.95 | AE7: 338587.28 | AF7: 242642.86 | AG7: 830714.06 | AH7: 25988.8 | AI7: 583286.3 | AJ7: 282254.71 | AK7: 27314.612 | AL7: 486629.49 | AM7: 582403.49 | AN7: 720049.64 | AO7: 599687.03 | AP7: 679.4625 | AQ7: 69173.925 | AR7: 247409.96 | AS7: 3470.9625 | AT7: 16363.938 | AU7: 2261575.2 | AV7: 456340.21 | AW7: 317783.78 | AX7: 420815.05 | AY7: 4796.45 | AZ7: 8540.3125 | BA7: 14264.712 | BB7: 747.4125 | BC7: 959.925 | BD7: 1353.45 | BE7: 2613.525 | BF7: 318.3125 | BG7: 5635.8 | BH7: 832.6 | BI7: 0 | BJ7: 1229.0125 | BK7: 1042.7375 | BL7: 2800.05 | BM7: 1832.0375 | BN7: 945.325 | BO7: 1102.525 | BP7: 1148.05 | BQ7: 89.1125 | BR7: 0 | BS7: 6395.3875 | BT7: 3142.6625 | BU7: 955.1 | BV7: 1028.0375 | BW7: 5456.9091 | BX7: 3848.8182 | BY7: 13744.33 | BZ7: 2365.2727 | CA7: 3911.6023 | CB7: 3562.3182 | CC7: 4370.0227 | CD7: 623.15909 | CE7: 8777.5114 | CF7: 2640.6818 | CG7: 406.86364 | CH7: 3746.1477 | CI7: 2953.1932 | CJ7: 5519.3295 | CK7: 5751.6932 | CL7: 318.92045 | CM7: 534.39773 | CN7: 2600.8409 | CO7: 184.29545 | CP7: 1402.4659 | CQ7: 3963.2045 | CR7: 4482.7159 | CS7: 2924.8977 | CT7: 3935.3068 | CU7: 279.85 | CV7: 232.35 | CW7: 417.2125 | CX7: 0 | CY7: 6.85 | CZ7: 231.525 | DA7: 231.475 | DB7: 63.7125 | DC7: 307.9125 | DD7: 125.175 | DE7: 135.15 | DF7: 289.5375 | DG7: 168.1 | DH7: 396.1625 | DI7: 237.975 | DJ7: 0 | DK7: 18.1 | DL7: 162.4125 | DM7: 262.3 | DN7: 206.25 | DO7: 77.975 | DP7: 143.3 | DQ7: 145.875 | DR7: 94.6125 | DS7: 9971.6705 | DT7: 20568.023 | DU7: 106958.12 | DV7: 1414.9091 | DW7: 2132.5795 | DX7: 4661.5341 | DY7: 47085.205 | DZ7: 300.90909 | EA7: 5896.4091 | EB7: 1419.5909 | EC7: 575.625 | ED7: 4688.2159 | EE7: 2148.9205 | EF7: 5757.8409 | EG7: 7166.0682 | EH7: 913.06818 | EI7: 3378.7045 | EJ7: 1746.1477 | EK7: 264.89773 | EL7: 348.56818 | EM7: 47558.136 | EN7: 41791.795 | EO7: 1656.1364 | EP7: 4036.8636 | EQ7: 188.69231 | ER7: 223.80769 | ES7: 1638.8173 | ET7: 86.894231 | EU7: 124.5 | EV7: 208.45192 | EW7: 239.66346 | EX7: 165.33654 | EY7: 92.817308 | EZ7: 312.34615 | FA7: 0 | FB7: 0 | FC7: 199.19231 | FD7: 160.89423 | FE7: 5.0384615 | FF7: 210.56731 | FG7: 103.42308 | FH7: 201.64423 | FI7: 119.72115 | FJ7: 0 | FK7: 107.09615 | FL7: 180.15385 | FM7: 361.94231 | FN7: 107.38462 | FO7: =IF((Pasted_data!C5-Pasted_data!C$148)<0,0,Pasted_data!C5-Pasted_data!C$148) -> 696771.12 | FP7: =IF((Pasted_data!D5-Pasted_data!D$148)<0,0,Pasted_data!D5-Pasted_data!D$148) -> 647176.67 | FQ7: =IF((Pasted_data!E5-Pasted_data!E$148)<0,0,Pasted_data!E5-Pasted_data!E$148) -> 557405.39 | FR7: =IF((Pasted_data!F5-Pasted_data!F$148)<0,0,Pasted_data!F5-Pasted_data!F$148) -> 464670.73 | FS7: =IF((Pasted_data!G5-Pasted_data!G$148)<0,0,Pasted_data!G5-Pasted_data!G$148) -> 608941.27 | FT7: =IF((Pasted_data!H5-Pasted_data!H$148)<0,0,Pasted_data!H5-Pasted_data!H$148) -> 488675.61 | FU7: =IF((Pasted_data!I5-Pasted_data!I$148)<0,0,Pasted_data!I5-Pasted_data!I$148) -> 834408.48 | FV7: =IF((Pasted_data!J5-Pasted_data!J$148)<0,0,Pasted_data!J5-Pasted_data!J$148) -> 231349.07 | ... JF7: =IF((Pasted_data!CT5-Pasted_data!CT$148)<0,0,Pasted_data!CT5-Pasted_data!CT$148) -> 989065.17 | JG7: 749938.54 | JH7: 1014064.2 | JI7: 944114.46 | JJ7: 1029143.4 | JK7: 503913 | JL7: 908695 | JM7: 881349.53 | JN7: 885043.88 | JO7: 727124.54 | JP7: 806095.01 | JQ7: 571848.63 | JR7: 40244.096 | JS7: 21671.962 | JT7: 93617.673 | JU7: 930475.72 | JV7: 807078.4 | JW7: 526518.43 | JX7: 809408.63 | JY7: 157934.41 | JZ7: 94373.471 | KA7: 28900.25 | KB7: 892455.46 | KC7: 38799.74 | KD7: 45977.885
A8: Mother | B8: 226699 | C8: 11508 | D8: 3193.2885 | E8: 42842.135 | F8: 1923.2115 | G8: 985.5 | H8: 2192.9231 | I8: 8666.9231 | J8: 827.46154 | K8: 50804.846 | L8: 1318 | M8: 2862.3077 | N8: 1962.3654 | O8: 1900.9808 | P8: 3915.3462 | Q8: 1180.6923 | R8: 4841.9231 | S8: 14671.462 | T8: 2182.7308 | U8: 3810.2308 | V8: 9967.9615 | W8: 6985.7308 | X8: 4605.2885 | Y8: 1842.5962 | Z8: 4968.0769 | AA8: 793114.37 | AB8: 164338.71 | AC8: 815433.15 | AD8: 17342.788 | AE8: 54020.731 | AF8: 44021.692 | AG8: 579010.79 | AH8: 637.86538 | AI8: 614491.38 | AJ8: 54010.154 | AK8: 2562 | AL8: 187546.54 | AM8: 59806.462 | AN8: 123310.42 | AO8: 74599.538 | AP8: 2519.0769 | AQ8: 145437.71 | AR8: 35496.269 | AS8: 1446.4423 | AT8: 8439.2115 | AU8: 6942.7692 | AV8: 141992.08 | AW8: 49287.75 | AX8: 314455.96 | AY8: 13741.635 | AZ8: 1464.0962 | BA8: 31689.096 | BB8: 659.73077 | BC8: 743.09615 | BD8: 334.53846 | BE8: 4563.9231 | BF8: 153.73077 | BG8: 7414.5 | BH8: 557.90385 | BI8: 747.26923 | BJ8: 575.55769 | BK8: 800.05769 | BL8: 1377.0385 | BM8: 407.13462 | BN8: 3839.2115 | BO8: 1612.9808 | BP8: 656.5 | BQ8: 532.23077 | BR8: 400.92308 | BS8: 3365.7308 | BT8: 1797.9038 | BU8: 447.67308 | BV8: 1741.25 | BW8: 8272.9038 | BX8: 1449.3077 | BY8: 12088.635 | BZ8: 1235.1923 | CA8: 887.01923 | CB8: 1601.5577 | CC8: 2978.5962 | CD8: 242.57692 | CE8: 5335.4231 | CF8: 753.67308 | CG8: 836.92308 | CH8: 1233.3846 | CI8: 1250.3269 | CJ8: 1776.6538 | CK8: 3476.6346 | CL8: 40.153846 | CM8: 2165.1346 | CN8: 1271.3269 | CO8: 10560.519 | CP8: 478.17308 | CQ8: 2710.2692 | CR8: 2098.5192 | CS8: 919.01923 | CT8: 1647.6154 | CU8: 1497.0385 | CV8: 222.01923 | CW8: 3185.2692 | CX8: 132.34615 | CY8: 518.44231 | CZ8: 177.73077 | DA8: 72.096154 | DB8: 0 | DC8: 966.73077 | DD8: 284.26923 | DE8: 0 | DF8: 104.59615 | DG8: 304.88462 | DH8: 5185.5962 | DI8: 232.59615 | DJ8: 115.26923 | DK8: 148.19231 | DL8: 448.55769 | DM8: 264.28846 | DN8: 0 | DO8: 1276.4423 | DP8: 472.92308 | DQ8: 229.53846 | DR8: 621 | DS8: 23969.058 | DT8: 2106.1346 | DU8: 34670.673 | DV8: 1084.6731 | DW8: 329.86538 | DX8: 1549.5 | DY8: 3944.3654 | DZ8: 155.63462 | EA8: 11578.615 | EB8: 748.73077 | EC8: 1438.7692 | ED8: 1671.3077 | EE8: 1463.8077 | EF8: 3344.4615 | EG8: 1699.3269 | EH8: 817.44231 | EI8: 4225.4423 | EJ8: 1143.5962 | EK8: 257.92308 | EL8: 602.65385 | EM8: 2852.0769 | EN8: 2598.6923 | EO8: 967.30769 | EP8: 2775.8462 | EQ8: 360.69231 | ER8: 134.55769 | ES8: 1124.0673 | ET8: 179.14423 | EU8: 266.5 | EV8: 151.45192 | EW8: 43.163462 | EX8: 1.8365385 | EY8: 0 | EZ8: 326.09615 | FA8: 62.884615 | FB8: 28.298077 | FC8: 106.69231 | FD8: 41.394231 | FE8: 96.288462 | FF8: 45.317308 | FG8: 0 | FH8: 14.394231 | FI8: 37.221154 | FJ8: 0 | FK8: 25.596154 | FL8: 143.15385 | FM8: 118.69231 | FN8: 0 | FO8: =IF((Pasted_data!C54-Pasted_data!C$148)<0,0,Pasted_data!C54-Pasted_data!C$148) -> 797192.12 | FP8: =IF((Pasted_data!D54-Pasted_data!D$148)<0,0,Pasted_data!D54-Pasted_data!D$148) -> 602782.42 | FQ8: =IF((Pasted_data!E54-Pasted_data!E$148)<0,0,Pasted_data!E54-Pasted_data!E$148) -> 614103.14 | FR8: =IF((Pasted_data!F54-Pasted_data!F$148)<0,0,Pasted_data!F54-Pasted_data!F$148) -> 395021.23 | FS8: =IF((Pasted_data!G54-Pasted_data!G$148)<0,0,Pasted_data!G54-Pasted_data!G$148) -> 429996.77 | FT8: =IF((Pasted_data!H54-Pasted_data!H$148)<0,0,Pasted_data!H54-Pasted_data!H$148) -> 300400.11 | FU8: =IF((Pasted_data!I54-Pasted_data!I$148)<0,0,Pasted_data!I54-Pasted_data!I$148) -> 596390.98 | FV8: =IF((Pasted_data!J54-Pasted_data!J$148)<0,0,Pasted_data!J54-Pasted_data!J$148) -> 49182.567 | ... JF8: =IF((Pasted_data!CT54-Pasted_data!CT$148)<0,0,Pasted_data!CT54-Pasted_data!CT$148) -> 1135912.2 | JG8: 431606.04 | JH8: 907808.92 | JI8: 916427.96 | JJ8: 1001337.9 | JK8: 749187.5 | JL8: 689401.75 | JM8: 572862.03 | JN8: 966960.88 | JO8: 395383.79 | JP8: 801540.26 | JQ8: 97224.635 | JR8: 27400.596 | JS8: 10331.712 | JT8: 35458.423 | JU8: 671625.97 | JV8: 802578.15 | JW8: 130303.93 | JX8: 674150.13 | JY8: 202346.91 | JZ8: 60911.971 | KA8: 44957.25 | KB8: 415725.96 | KC8: 56372.74 | KD8: 100036.38
A9: Mother | B9: 238216 | C9: 24889.08 | D9: 3153.4659 | E9: 81578.136 | F9: 27728.443 | G9: 2107.8295 | H9: 2727.1591 | I9: 7433.3977 | J9: 3888.9432 | K9: 94052.102 | L9: 37446.602 | M9: 6329.2159 | N9: 5321.5455 | O9: 40350.58 | P9: 48565.205 | Q9: 5388.6932 | R9: 4835 | S9: 18269.943 | T9: 17427.193 | U9: 2393.3068 | V9: 2776.9659 | W9: 55433.5 | X9: 10638.25 | Y9: 40143.5 | Z9: 3146.6136 | AA9: 1067612.4 | AB9: 719448.19 | AC9: 1712514.8 | AD9: 248621.2 | AE9: 260034.27 | AF9: 441799.61 | AG9: 1502019.6 | AH9: 38048.3 | AI9: 723276.05 | AJ9: 115073.21 | AK9: 60180.363 | AL9: 1294144.7 | AM9: 437589.24 | AN9: 662799.39 | AO9: 701796.78 | AP9: 455.7125 | AQ9: 25673.425 | AR9: 152827.96 | AS9: 993.9625 | AT9: 43144.938 | AU9: 2368400.2 | AV9: 571734.46 | AW9: 141847.02 | AX9: 491359.55 | AY9: 42094.2 | AZ9: 1205.3125 | BA9: 9040.2125 | BB9: 1661.9125 | BC9: 8834.175 | BD9: 4751.95 | BE9: 1779.525 | BF9: 257.8125 | BG9: 11181.8 | BH9: 1742.85 | BI9: 444.475 | BJ9: 22289.013 | BK9: 3407.2375 | BL9: 7983.8 | BM9: 13833.538 | BN9: 331.325 | BO9: 493.275 | BP9: 2290.05 | BQ9: 266.3625 | BR9: 883.8875 | BS9: 120487.14 | BT9: 1321.6625 | BU9: 2247.35 | BV9: 15641.788 | BW9: 28373.659 | BX9: 5916.3182 | BY9: 17535.58 | BZ9: 1481.0227 | CA9: 8419.6023 | CB9: 13250.568 | CC9: 16055.523 | CD9: 216.40909 | CE9: 24229.011 | CF9: 2229.1818 | CG9: 201.11364 | CH9: 12788.398 | CI9: 3127.9432 | CJ9: 5751.0795 | CK9: 67856.193 | CL9: 216.67045 | CM9: 472.39773 | CN9: 3489.5909 | CO9: 673.04545 | CP9: 321.96591 | CQ9: 3997.9545 | CR9: 5915.2159 | CS9: 2862.1477 | CT9: 10602.807 | CU9: 2136.85 | CV9: 386.6 | CW9: 2544.4625 | CX9: 15875.413 | CY9: 66018.85 | CZ9: 732.025 | DA9: 794.475 | DB9: 5799.9625 | DC9: 1264.9125 | DD9: 14040.925 | DE9: 329.15 | DF9: 1141.7875 | DG9: 23470.85 | DH9: 33788.162 | DI9: 1219.475 | DJ9: 23.5625 | DK9: 246.35 | DL9: 20135.912 | DM9: 0 | DN9: 292 | DO9: 4681.975 | DP9: 654.8 | DQ9: 16888.375 | DR9: 734.3625 | DS9: 19186.42 | DT9: 14370.273 | DU9: 52601.125 | DV9: 4538.9091 | DW9: 2631.0795 | DX9: 7063.5341 | DY9: 15722.705 | DZ9: 1063.1591 | EA9: 22065.659 | EB9: 4425.8409 | EC9: 1767.875 | ED9: 19242.216 | EE9: 7198.6705 | EF9: 8629.0909 | EG9: 15887.318 | EH9: 2131.0682 | EI9: 844.70455 | EJ9: 4659.3977 | EK9: 436.64773 | EL9: 4103.8182 | EM9: 137472.39 | EN9: 9781.2955 | EO9: 5345.3864 | EP9: 12389.864 | EQ9: 586.19231 | ER9: 30.057692 | ES9: 478.56731 | ET9: 290.39423 | EU9: 112.5 | EV9: 260.20192 | EW9: 167.16346 | EX9: 146.33654 | EY9: 56.317308 | EZ9: 373.59615 | FA9: 105.63462 | FB9: 92.298077 | FC9: 30.692308 | FD9: 89.894231 | FE9: 65.038462 | FF9: 209.81731 | FG9: 281.17308 | FH9: 336.39423 | FI9: 2.2211538 | FJ9: 134.44231 | FK9: 0 | FL9: 70.403846 | FM9: 153.69231 | FN9: 124.88462 | FO9: =IF((Pasted_data!C6-Pasted_data!C$148)<0,0,Pasted_data!C6-Pasted_data!C$148) -> 999012.62 | FP9: =IF((Pasted_data!D6-Pasted_data!D$148)<0,0,Pasted_data!D6-Pasted_data!D$148) -> 720811.42 | FQ9: =IF((Pasted_data!E6-Pasted_data!E$148)<0,0,Pasted_data!E6-Pasted_data!E$148) -> 652292.14 | FR9: =IF((Pasted_data!F6-Pasted_data!F$148)<0,0,Pasted_data!F6-Pasted_data!F$148) -> 332926.73 | FS9: =IF((Pasted_data!G6-Pasted_data!G$148)<0,0,Pasted_data!G6-Pasted_data!G$148) -> 555005.02 | FT9: =IF((Pasted_data!H6-Pasted_data!H$148)<0,0,Pasted_data!H6-Pasted_data!H$148) -> 678540.11 | FU9: =IF((Pasted_data!I6-Pasted_data!I$148)<0,0,Pasted_data!I6-Pasted_data!I$148) -> 949302.23 | FV9: =IF((Pasted_data!J6-Pasted_data!J$148)<0,0,Pasted_data!J6-Pasted_data!J$148) -> 150141.57 | ... JF9: =IF((Pasted_data!CT6-Pasted_data!CT$148)<0,0,Pasted_data!CT6-Pasted_data!CT$148) -> 944091.42 | JG9: 361988.04 | JH9: 902070.17 | JI9: 1011684.2 | JJ9: 1022142.1 | JK9: 644735.25 | JL9: 834546 | JM9: 852212.03 | JN9: 904534.63 | JO9: 294308.29 | JP9: 307471.26 | JQ9: 819572.38 | JR9: 43572.596 | JS9: 8501.2115 | JT9: 29047.423 | JU9: 992079.97 | JV9: 251902.15 | JW9: 95528.933 | JX9: 914615.13 | JY9: 375675.41 | JZ9: 26402.721 | KA9: 25831.75 | KB9: 163088.96 | KC9: 34187.74 | KD9: 110760.38
A10: Mother | B10: 255243 | C10: 15761 | D10: 2633.7885 | E10: 80443.885 | F10: 2233.7115 | G10: 1214.25 | H10: 3804.9231 | I10: 3488.9231 | J10: 674.21154 | K10: 47190.846 | L10: 2860.5 | M10: 3335.3077 | N10: 2730.6154 | O10: 1597.4808 | P10: 29161.346 | Q10: 2976.6923 | R10: 8010.9231 | S10: 21954.712 | T10: 2666.2308 | U10: 4961.2308 | V10: 6162.9615 | W10: 11137.481 | X10: 7143.2885 | Y10: 3242.8462 | Z10: 11344.077 | AA10: 16477.615 | AB10: 299.96154 | AC10: 0 | AD10: 0 | AE10: 0 | AF10: 74.692308 | AG10: 7332.7885 | AH10: 0 | AI10: 5911.6346 | AJ10: 0 | AK10: 0 | AL10: 6203.5385 | AM10: 0 | AN10: 0 | AO10: 92.038462 | AP10: 299.32692 | AQ10: 21.961538 | AR10: 0 | AS10: 222.19231 | AT10: 3468.9615 | AU10: 2479.0192 | AV10: 218.07692 | AW10: 0 | AX10: 148.46154 | AY10: 1677.3846 | AZ10: 657.09615 | BA10: 33278.346 | BB10: 851.48077 | BC10: 771.34615 | BD10: 300.53846 | BE10: 3788.4231 | BF10: 0 | BG10: 11082 | BH10: 471.90385 | BI10: 460.76923 | BJ10: 336.05769 | BK10: 814.80769 | BL10: 2175.5385 | BM10: 126.63462 | BN10: 1355.7115 | BO10: 852.73077 | BP10: 477.75 | BQ10: 1228.4808 | BR10: 462.17308 | BS10: 3188.7308 | BT10: 830.40385 | BU10: 935.92308 | BV10: 556 | BW10: 2309.4038 | BX10: 648.80769 | BY10: 18413.385 | BZ10: 2221.4423 | CA10: 11928.019 | CB10: 823.80769 | CC10: 725.09615 | CD10: 242.32692 | CE10: 7314.4231 | CF10: 3331.6731 | CG10: 657.92308 | CH10: 857.63462 | CI10: 2197.5769 | CJ10: 8807.9038 | CK10: 1276.3846 | CL10: 824.40385 | CM10: 1268.6346 | CN10: 4877.5769 | CO10: 273.26923 | CP10: 465.67308 | CQ10: 2285.2692 | CR10: 469.26923 | CS10: 3953.5192 | CT10: 1110.8654 | CU10: 327.78846 | CV10: 59.269231 | CW10: 4930.7692 | CX10: 1.3461538 | CY10: 143.44231 | CZ10: 12.480769 | DA10: 35.096154 | DB10: 40.807692 | DC10: 1795.9808 | DD10: 70.269231 | DE10: 0 | DF10: 0 | DG10: 53.634615 | DH10: 49.346154 | DI10: 174.59615 | DJ10: 120.76923 | DK10: 149.19231 | DL10: 9.0576923 | DM10: 0 | DN10: 317.42308 | DO10: 320.94231 | DP10: 188.67308 | DQ10: 124.28846 | DR10: 370.25 | DS10: 9338.0577 | DT10: 6241.1346 | DU10: 29513.923 | DV10: 1973.6731 | DW10: 3281.8654 | DX10: 3014.5 | DY10: 6689.6154 | DZ10: 732.13462 | EA10: 19106.615 | EB10: 4279.7308 | EC10: 1014.2692 | ED10: 4855.0577 | EE10: 2988.3077 | EF10: 6334.2115 | EG10: 4155.5769 | EH10: 480.44231 | EI10: 1706.4423 | EJ10: 5323.5962 | EK10: 618.67308 | EL10: 802.90385 | EM10: 2800.0769 | EN10: 11054.692 | EO10: 3845.0577 | EP10: 4060.8462 | EQ10: 154.19231 | ER10: 128.05769 | ES10: 1089.5673 | ET10: 0 | EU10: 13.75 | EV10: 0 | EW10: 92.413462 | EX10: 137.33654 | EY10: 0 | EZ10: 550.09615 | FA10: 31.634615 | FB10: 18.298077 | FC10: 74.192308 | FD10: 135.39423 | FE10: 69.288462 | FF10: 76.567308 | FG10: 714.42308 | FH10: 109.89423 | FI10: 137.72115 | FJ10: 17.942308 | FK10: 86.596154 | FL10: 0 | FM10: 0 | FN10: 0 | FO10: =IF((Pasted_data!C55-Pasted_data!C$148)<0,0,Pasted_data!C55-Pasted_data!C$148) -> 162365.88 | FP10: =IF((Pasted_data!D55-Pasted_data!D$148)<0,0,Pasted_data!D55-Pasted_data!D$148) -> 356078.67 | FQ10: =IF((Pasted_data!E55-Pasted_data!E$148)<0,0,Pasted_data!E55-Pasted_data!E$148) -> 0 | FR10: =IF((Pasted_data!F55-Pasted_data!F$148)<0,0,Pasted_data!F55-Pasted_data!F$148) -> 136209.73 | FS10: =IF((Pasted_data!G55-Pasted_data!G$148)<0,0,Pasted_data!G55-Pasted_data!G$148) -> 587507.27 | FT10: =IF((Pasted_data!H55-Pasted_data!H$148)<0,0,Pasted_data!H55-Pasted_data!H$148) -> 114970.11 | FU10: =IF((Pasted_data!I55-Pasted_data!I$148)<0,0,Pasted_data!I55-Pasted_data!I$148) -> 380651.73 | FV10: =IF((Pasted_data!J55-Pasted_data!J$148)<0,0,Pasted_data!J55-Pasted_data!J$148) -> 136084.57 | ... JF10: =IF((Pasted_data!CT55-Pasted_data!CT$148)<0,0,Pasted_data!CT55-Pasted_data!CT$148) -> 140888.67 | JG10: 61832.038 | JH10: 521512.67 | JI10: 827640.96 | JJ10: 8515.3942 | JK10: 33497.25 | JL10: 37295.25 | JM10: 36936.029 | JN10: 775491.63 | JO10: 72056.538 | JP10: 258722.51 | JQ10: 44872.635 | JR10: 11871.596 | JS10: 5049.7115 | JT10: 12098.423 | JU10: 744252.97 | JV10: 141859.9 | JW10: 37417.183 | JX10: 17332.635 | JY10: 0 | JZ10: 41035.721 | KA10: 16953.25 | KB10: 43948.462 | KC10: 15409.99 | KD10: 26306.385
A11: Mother | B11: 257416 | C11: 7153.3295 | D11: 8001.2159 | E11: 41440.136 | F11: 19384.193 | G11: 1678.8295 | H11: 2018.6591 | I11: 8020.8977 | J11: 654.44318 | K11: 16311.352 | L11: 36286.102 | M11: 1935.9659 | N11: 4283.0455 | O11: 37550.33 | P11: 48401.705 | Q11: 10509.443 | R11: 5819.5 | S11: 6274.1932 | T11: 8647.1932 | U11: 1385.8068 | V11: 2102.9659 | W11: 10325.75 | X11: 4895.25 | Y11: 39056.5 | Z11: 2680.6136 | AA11: 34577.412 | AB11: 42339.188 | AC11: 30313.25 | AD11: 11228.95 | AE11: 18514.275 | AF11: 3206.1125 | AG11: 31667.062 | AH11: 572.3 | AI11: 9598.8 | AJ11: 7471.2125 | AK11: 1368.1125 | AL11: 9350.2375 | AM11: 22762.737 | AN11: 67466.387 | AO11: 10754.775 | AP11: 0 | AQ11: 1708.925 | AR11: 58506.713 | AS11: 211.4625 | AT11: 10987.688 | AU11: 96593.663 | AV11: 21107.963 | AW11: 7350.025 | AX11: 12635.8 | AY11: 2229.7 | AZ11: 1331.5625 | BA11: 3693.2125 | BB11: 186.4125 | BC11: 184.425 | BD11: 486.95 | BE11: 902.025 | BF11: 216.8125 | BG11: 840.3 | BH11: 297.6 | BI11: 0 | BJ11: 456.0125 | BK11: 205.9875 | BL11: 1298.55 | BM11: 164.7875 | BN11: 416.825 | BO11: 646.525 | BP11: 602.05 | BQ11: 84.1125 | BR11: 554.1375 | BS11: 12881.638 | BT11: 1138.9125 | BU11: 393.85 | BV11: 769.7875 | BW11: 4645.4091 | BX11: 6617.8182 | BY11: 30400.58 | BZ11: 1194.2727 | CA11: 2206.6023 | CB11: 1231.0682 | CC11: 11265.023 | CD11: 407.40909 | CE11: 10393.761 | CF11: 1200.6818 | CG11: 1014.6136 | CH11: 1404.3977 | CI11: 1880.1932 | CJ11: 2938.5795 | CK11: 4567.1932 | CL11: 274.92045 | CM11: 1923.8977 | CN11: 1690.3409 | CO11: 502.54545 | CP11: 611.46591 | CQ11: 8557.9545 | CR11: 5767.7159 | CS11: 1778.8977 | CT11: 1477.8068 | CU11: 0 | CV11: 116.35 | CW11: 39.2125 | CX11: 0 | CY11: 87.85 | CZ11: 72.775 | DA11: 286.225 | DB11: 101.9625 | DC11: 144.4125 | DD11: 63.425 | DE11: 10.65 | DF11: 79.5375 | DG11: 131.1 | DH11: 127.9125 | DI11: 267.225 | DJ11: 0 | DK11: 99.6 | DL11: 0 | DM11: 0 | DN11: 169.5 | DO11: 133.725 | DP11: 118.55 | DQ11: 0 | DR11: 95.1125 | DS11: 33915.17 | DT11: 76467.773 | DU11: 78646.625 | DV11: 2355.6591 | DW11: 4706.5795 | DX11: 12132.284 | DY11: 12471.955 | DZ11: 999.15909 | EA11: 17624.159 | EB11: 2324.0909 | EC11: 5818.125 | ED11: 17939.466 | EE11: 3689.9205 | EF11: 8112.5909 | EG11: 25562.568 | EH11: 863.56818 | EI11: 2781.2045 | EJ11: 7493.1477 | EK11: 687.14773 | EL11: 2524.8182 | EM11: 395506.39 | EN11: 20354.795 | EO11: 2858.1364 | EP11: 18906.364 | EQ11: 699.69231 | ER11: 329.55769 | ES11: 1033.5673 | ET11: 52.394231 | EU11: 13.5 | EV11: 93.951923 | EW11: 68.913462 | EX11: 127.08654 | EY11: 29.317308 | EZ11: 229.84615 | FA11: 128.38462 | FB11: 286.29808 | FC11: 21.942308 | FD11: 240.89423 | FE11: 142.53846 | FF11: 95.817308 | FG11: 35.673077 | FH11: 111.64423 | FI11: 212.22115 | FJ11: 180.69231 | FK11: 0 | FL11: 972.40385 | FM11: 316.69231 | FN11: 23.384615 | FO11: =IF((Pasted_data!C7-Pasted_data!C$148)<0,0,Pasted_data!C7-Pasted_data!C$148) -> 620302.12 | FP11: =IF((Pasted_data!D7-Pasted_data!D$148)<0,0,Pasted_data!D7-Pasted_data!D$148) -> 692877.17 | FQ11: =IF((Pasted_data!E7-Pasted_data!E$148)<0,0,Pasted_data!E7-Pasted_data!E$148) -> 214558.39 | FR11: =IF((Pasted_data!F7-Pasted_data!F$148)<0,0,Pasted_data!F7-Pasted_data!F$148) -> 436876.23 | FS11: =IF((Pasted_data!G7-Pasted_data!G$148)<0,0,Pasted_data!G7-Pasted_data!G$148) -> 427687.77 | FT11: =IF((Pasted_data!H7-Pasted_data!H$148)<0,0,Pasted_data!H7-Pasted_data!H$148) -> 223941.61 | FU11: =IF((Pasted_data!I7-Pasted_data!I$148)<0,0,Pasted_data!I7-Pasted_data!I$148) -> 674181.73 | FV11: =IF((Pasted_data!J7-Pasted_data!J$148)<0,0,Pasted_data!J7-Pasted_data!J$148) -> 80853.817 | ... JF11: =IF((Pasted_data!CT7-Pasted_data!CT$148)<0,0,Pasted_data!CT7-Pasted_data!CT$148) -> 795399.92 | JG11: 527844.54 | JH11: 994572.92 | JI11: 926709.46 | JJ11: 864416.14 | JK11: 472023.25 | JL11: 954219 | JM11: 930391.28 | JN11: 147553.38 | JO11: 462433.29 | JP11: 429460.01 | JQ11: 29976.885 | JR11: 59828.096 | JS11: 8837.2115 | JT11: 23507.673 | JU11: 480816.47 | JV11: 365528.9 | JW11: 179996.93 | JX11: 929220.88 | JY11: 0 | JZ11: 125675.72 | KA11: 25390.75 | KB11: 931415.46 | KC11: 31759.24 | KD11: 617171.38
A12: Mother | B12: 281359 | C12: 53623.58 | D12: 4098.4659 | E12: 100942.14 | F12: 1462.1932 | G12: 7427.3295 | H12: 2545.9091 | I12: 5180.6477 | J12: 1140.6932 | K12: 21869.602 | L12: 8114.1023 | M12: 2034.2159 | N12: 3106.5455 | O12: 3519.0795 | P12: 80826.955 | Q12: 5621.4432 | R12: 12094.5 | S12: 9547.9432 | T12: 14294.943 | U12: 2682.5568 | V12: 2789.2159 | W12: 21578 | X12: 4701.25 | Y12: 14375.25 | Z12: 872.36364 | AA12: 463924.16 | AB12: 637750.94 | AC12: 1923827.8 | AD12: 750320.7 | AE12: 1702991.3 | AF12: 212795.11 | AG12: 912067.56 | AH12: 52792.8 | AI12: 496047.8 | AJ12: 1566129.5 | AK12: 112606.11 | AL12: 499103.49 | AM12: 1166739.2 | AN12: 2495103.6 | AO12: 360514.78 | AP12: 2174.2125 | AQ12: 358465.17 | AR12: 1749614.2 | AS12: 14569.962 | AT12: 80827.188 | AU12: 2216604.2 | AV12: 599877.96 | AW12: 1795957 | AX12: 131489.55 | AY12: 3736.95 | AZ12: 1294.5625 | BA12: 9124.4625 | BB12: 5134.4125 | BC12: 17572.925 | BD12: 657.2 | BE12: 1843.525 | BF12: 1568.5625 | BG12: 6392.3 | BH12: 9817.35 | BI12: 168.225 | BJ12: 1365.5125 | BK12: 7824.4875 | BL12: 14744.8 | BM12: 1020.0375 | BN12: 1779.075 | BO12: 1004.025 | BP12: 10422.55 | BQ12: 0 | BR12: 178.6375 | BS12: 38008.637 | BT12: 1583.4125 | BU12: 10545.1 | BV12: 1362.0375 | BW12: 4307.6591 | BX12: 1012.3182 | BY12: 19777.58 | BZ12: 6642.2727 | CA12: 7667.6023 | CB12: 977.31818 | CC12: 4368.7727 | CD12: 216.65909 | CE12: 4767.2614 | CF12: 4483.1818 | CG12: 330.86364 | CH12: 1102.1477 | CI12: 5580.4432 | CJ12: 6477.0795 | CK12: 3503.6932 | CL12: 1178.9205 | CM12: 534.39773 | CN12: 2929.8409 | CO12: 273.79545 | CP12: 298.96591 | CQ12: 5746.4545 | CR12: 888.96591 | CS12: 5033.3977 | CT12: 767.80682 | CU12: 459.35 | CV12: 460.6 | CW12: 2164.2125 | CX12: 280.6625 | CY12: 1429.1 | CZ12: 379.025 | DA12: 822.975 | DB12: 313.7125 | DC12: 536.4125 | DD12: 1035.675 | DE12: 314.65 | DF12: 333.0375 | DG12: 791.35 | DH12: 2045.4125 | DI12: 389.975 | DJ12: 254.3125 | DK12: 37.1 | DL12: 954.6625 | DM12: 279.05 | DN12: 0 | DO12: 1282.725 | DP12: 399.8 | DQ12: 1427.125 | DR12: 430.3625 | DS12: 20313.17 | DT12: 6443.5227 | DU12: 57817.875 | DV12: 21179.409 | DW12: 11105.08 | DX12: 5428.0341 | DY12: 14092.205 | DZ12: 674.65909 | EA12: 8576.6591 | EB12: 43058.341 | EC12: 1943.125 | ED12: 10640.466 | EE12: 30594.17 | EF12: 86877.841 | EG12: 10414.568 | EH12: 706.81818 | EI12: 1821.2045 | EJ12: 32349.648 | EK12: 587.39773 | EL12: 2254.5682 | EM12: 70691.386 | EN12: 9754.5455 | EO12: 48734.886 | EP12: 4576.1136 | EQ12: 479.44231 | ER12: 146.55769 | ES12: 1379.5673 | ET12: 318.89423 | EU12: 260.5 | EV12: 137.45192 | EW12: 28.913462 | EX12: 158.33654 | EY12: 65.317308 | EZ12: 698.09615 | FA12: 1163.6346 | FB12: 126.29808 | FC12: 273.69231 | FD12: 533.14423 | FE12: 2763.7885 | FF12: 143.31731 | FG12: 725.17308 | FH12: 119.39423 | FI12: 851.22115 | FJ12: 88.442308 | FK12: 180.84615 | FL12: 985.65385 | FM12: 203.44231 | FN12: 1118.3846 | FO12: =IF((Pasted_data!C8-Pasted_data!C$148)<0,0,Pasted_data!C8-Pasted_data!C$148) -> 598729.12 | FP12: =IF((Pasted_data!D8-Pasted_data!D$148)<0,0,Pasted_data!D8-Pasted_data!D$148) -> 563802.92 | FQ12: =IF((Pasted_data!E8-Pasted_data!E$148)<0,0,Pasted_data!E8-Pasted_data!E$148) -> 666568.64 | FR12: =IF((Pasted_data!F8-Pasted_data!F$148)<0,0,Pasted_data!F8-Pasted_data!F$148) -> 649214.73 | FS12: =IF((Pasted_data!G8-Pasted_data!G$148)<0,0,Pasted_data!G8-Pasted_data!G$148) -> 1068941.3 | FT12: =IF((Pasted_data!H8-Pasted_data!H$148)<0,0,Pasted_data!H8-Pasted_data!H$148) -> 253722.11 | FU12: =IF((Pasted_data!I8-Pasted_data!I$148)<0,0,Pasted_data!I8-Pasted_data!I$148) -> 612971.98 | FV12: =IF((Pasted_data!J8-Pasted_data!J$148)<0,0,Pasted_data!J8-Pasted_data!J$148) -> 116196.57 | ... JF12: =IF((Pasted_data!CT8-Pasted_data!CT$148)<0,0,Pasted_data!CT8-Pasted_data!CT$148) -> 494214.92 | JG12: 854505.54 | JH12: 1017933.2 | JI12: 613353.46 | JJ12: 929056.39 | JK12: 27331.5 | JL12: 804388.25 | JM12: 698374.53 | JN12: 496461.88 | JO12: 1029355.8 | JP12: 947947.01 | JQ12: 38497.635 | JR12: 70415.096 | JS12: 14592.712 | JT12: 32955.423 | JU12: 627032.47 | JV12: 1000295.7 | JW12: 653193.43 | JX12: 733191.13 | JY12: 0 | JZ12: 544805.72 | KA12: 32212.75 | KB12: 935662.21 | KC12: 24097.49 | KD12: 54243.385
A13: Mother | B13: 316629 | C13: 31589.25 | D13: 4690.5385 | E13: 67532.635 | F13: 18361.712 | G13: 1733 | H13: 1993.4231 | I13: 5155.6731 | J13: 1612.9615 | K13: 44306.346 | L13: 41892.25 | M13: 2406.5577 | N13: 2235.6154 | O13: 26422.231 | P13: 43447.846 | Q13: 726.44231 | R13: 15943.923 | S13: 47847.212 | T13: 9826.9808 | U13: 5860.2308 | V13: 6780.2115 | W13: 8499.2308 | X13: 2881.5385 | Y13: 40375.846 | Z13: 6120.5769 | AA13: 262.86538 | AB13: 555.71154 | AC13: 32471.654 | AD13: 0 | AE13: 0 | AF13: 0 | AG13: 20773.038 | AH13: 0 | AI13: 0 | AJ13: 0 | AK13: 0 | AL13: 181.53846 | AM13: 0 | AN13: 8808.9231 | AO13: 361.03846 | AP13: 197.57692 | AQ13: 443.71154 | AR13: 0 | AS13: 168.19231 | AT13: 5420.4615 | AU13: 609.76923 | AV13: 680.57692 | AW13: 0 | AX13: 144.96154 | AY13: 452.63462 | AZ13: 139.84615 | BA13: 9653.5962 | BB13: 0 | BC13: 0 | BD13: 169.53846 | BE13: 585.67308 | BF13: 0 | BG13: 1746.25 | BH13: 212.65385 | BI13: 0 | BJ13: 175.30769 | BK13: 363.05769 | BL13: 881.78846 | BM13: 0 | BN13: 401.46154 | BO13: 10424.481 | BP13: 0 | BQ13: 22.980769 | BR13: 121.17308 | BS13: 1274.2308 | BT13: 267.15385 | BU13: 359.17308 | BV13: 146.25 | BW13: 2548.1538 | BX13: 2376.8077 | BY13: 19200.635 | BZ13: 2067.9423 | CA13: 6830.2692 | CB13: 1241.8077 | CC13: 2556.5962 | CD13: 520.32692 | CE13: 7078.4231 | CF13: 2303.4231 | CG13: 824.42308 | CH13: 644.13462 | CI13: 3044.0769 | CJ13: 6394.4038 | CK13: 589.63462 | CL13: 842.90385 | CM13: 898.88462 | CN13: 3244.5769 | CO13: 451.76923 | CP13: 0 | CQ13: 1818.7692 | CR13: 1748.7692 | CS13: 2939.2692 | CT13: 991.61538 | CU13: 0 | CV13: 226.51923 | CW13: 1215.2692 | CX13: 74.596154 | CY13: 173.69231 | CZ13: 0 | DA13: 0 | DB13: 52.807692 | DC13: 498.98077 | DD13: 0 | DE13: 0 | DF13: 130.34615 | DG13: 0 | DH13: 12.596154 | DI13: 0 | DJ13: 0 | DK13: 191.19231 | DL13: 470.55769 | DM13: 670.53846 | DN13: 384.92308 | DO13: 0 | DP13: 94.923077 | DQ13: 246.53846 | DR13: 0 | DS13: 2642.3077 | DT13: 3606.8846 | DU13: 49527.423 | DV13: 721.42308 | DW13: 978.11538 | DX13: 1498.75 | DY13: 5769.1154 | DZ13: 212.63462 | EA13: 9440.6154 | EB13: 950.73077 | EC13: 128.76923 | ED13: 2813.3077 | EE13: 1606.3077 | EF13: 3362.9615 | EG13: 295.82692 | EH13: 679.19231 | EI13: 2751.9423 | EJ13: 1085.8462 | EK13: 228.42308 | EL13: 0 | EM13: 5346.8269 | EN13: 3627.4423 | EO13: 1330.0577 | EP13: 835.59615 | EQ13: 145.44231 | ER13: 150.05769 | ES13: 1128.3173 | ET13: 103.39423 | EU13: 55.5 | EV13: 72.951923 | EW13: 0 | EX13: 76.336538 | EY13: 0 | EZ13: 431.84615 | FA13: 191.13462 | FB13: 54.298077 | FC13: 58.692308 | FD13: 97.394231 | FE13: 90.788462 | FF13: 0 | FG13: 0 | FH13: 141.89423 | FI13: 27.721154 | FJ13: 135.69231 | FK13: 0 | FL13: 0 | FM13: 109.19231 | FN13: 147.13462 | FO13: =IF((Pasted_data!C56-Pasted_data!C$148)<0,0,Pasted_data!C56-Pasted_data!C$148) -> 300312.38 | FP13: =IF((Pasted_data!D56-Pasted_data!D$148)<0,0,Pasted_data!D56-Pasted_data!D$148) -> 465040.17 | FQ13: =IF((Pasted_data!E56-Pasted_data!E$148)<0,0,Pasted_data!E56-Pasted_data!E$148) -> 679385.89 | FR13: =IF((Pasted_data!F56-Pasted_data!F$148)<0,0,Pasted_data!F56-Pasted_data!F$148) -> 315615.48 | FS13: =IF((Pasted_data!G56-Pasted_data!G$148)<0,0,Pasted_data!G56-Pasted_data!G$148) -> 717068.77 | FT13: =IF((Pasted_data!H56-Pasted_data!H$148)<0,0,Pasted_data!H56-Pasted_data!H$148) -> 63721.856 | FU13: =IF((Pasted_data!I56-Pasted_data!I$148)<0,0,Pasted_data!I56-Pasted_data!I$148) -> 742866.73 | FV13: =IF((Pasted_data!J56-Pasted_data!J$148)<0,0,Pasted_data!J56-Pasted_data!J$148) -> 92240.067 | ... JF13: =IF((Pasted_data!CT56-Pasted_data!CT$148)<0,0,Pasted_data!CT56-Pasted_data!CT$148) -> 49945.173 | JG13: 72631.038 | JH13: 734069.67 | JI13: 0 | JJ13: 887116.64 | JK13: 2883.5 | JL13: 45842.5 | JM13: 34802.279 | JN13: 7656.3846 | JO13: 12974.538 | JP13: 353259.26 | JQ13: 0 | JR13: 4452.5962 | JS13: 2611.4615 | JT13: 6582.4231 | JU13: 2706.4712 | JV13: 188960.15 | JW13: 11904.183 | JX13: 40837.885 | JY13: 0 | JZ13: 6278.4712 | KA13: 4744.75 | KB13: 64846.462 | KC13: 8000.2404 | KD13: 11175.885
