Workbook

Sheet Milk_PBS_corrected_numeric
A1: Subject ID | B1: Barcode | C1: Delta_weeks | D1: Time_point | E1: Vax_timing_bin | F1: IgM_A_California_04_2009_H1N1 | G1: IgM_A_Michigan_45_2015_H1N1 | H1: IgM_A_Brisbane_02_2018_H1N1 | I1: IgM_A_Victoria_2570_2019_H1N1 | J1: IgM_A_Wisconsin_588_2019_H1N1 | K1: IgM_A_Hawaii_70_2019_H1N1 | L1: IgM_A_Wisconsin_67_2022_H1N1 | M1: IgM_A_HongKong_4801_2014_H3N2 | N1: IgM_A_Singapore_INFIMH16_2016_H3N2 | O1: IgM_A_Kansas_14_2017_H3N2 | P1: IgM_A_HongKong_45_2019_H3N2 | Q1: IgM_A_Cambodia_e0826360_2020_H3N2 | R1: IgM_A_Darwin_6_2021_H3N2 | S1: IgM_A_Indonesia_05_2005_H5N1 | T1: IgM_A_Shanghai_1_2013_H7N9 | U1: IgM_B_Phuket_3073_2013 | V1: IgM_B_Colorado_06_2017 | W1: IgM_B_Washington_02_2019 | X1: IgM_B_Austria_1359417_2021 | Y1: IgM_Michigan_NA | Z1: IgM_HongKong_NA | AA1: IgM_Ebola | AB1: IgM_RSV | AC1: IgM_EBV | AD1: IgG1_A_California_04_2009_H1N1 | AE1: IgG1_A_Michigan_45_2015_H1N1 | AF1: IgG1_A_Brisbane_02_2018_H1N1 | AG1: IgG1_A_Victoria_2570_2019_H1N1 | AH1: IgG1_A_Wisconsin_588_2019_H1N1 | AI1: IgG1_A_Hawaii_70_2019_H1N1 | AJ1: IgG1_A_Wisconsin_67_2022_H1N1 | AK1: IgG1_A_HongKong_4801_2014_H3N2 | AL1: IgG1_A_Singapore_INFIMH16_2016_H3N2 | AM1: IgG1_A_Kansas_14_2017_H3N2 | AN1: IgG1_A_HongKong_45_2019_H3N2 | AO1: IgG1_A_Cambodia_e0826360_2020_H3N2 | AP1: IgG1_A_Darwin_6_2021_H3N2 | AQ1: IgG1_A_Indonesia_05_2005_H5N1 | AR1: IgG1_A_Shanghai_1_2013_H7N9 | AS1: IgG1_B_Phuket_3073_2013 | AT1: IgG1_B_Colorado_06_2017 | AU1: IgG1_B_Washington_02_2019 | AV1: IgG1_B_Austria_1359417_2021 | AW1: IgG1_Michigan_NA | AX1: IgG1_HongKong_NA | AY1: IgG1_Ebola | AZ1: IgG1_RSV | BA1: IgG1_EBV | BB1: IgG2_A_California_04_2009_H1N1 | BC1: IgG2_A_Michigan_45_2015_H1N1 | BD1: IgG2_A_Brisbane_02_2018_H1N1 | BE1: IgG2_A_Victoria_2570_2019_H1N1 | BF1: IgG2_A_Wisconsin_588_2019_H1N1 | BG1: IgG2_A_Hawaii_70_2019_H1N1 | BH1: IgG2_A_Wisconsin_67_2022_H1N1 | BI1: IgG2_A_HongKong_4801_2014_H3N2 | BJ1: IgG2_A_Singapore_INFIMH16_2016_H3N2 | BK1: IgG2_A_Kansas_14_2017_H3N2 | BL1: IgG2_A_HongKong_45_2019_H3N2 | BM1: IgG2_A_Cambodia_e0826360_2020_H3N2 | BN1: IgG2_A_Darwin_6_2021_H3N2 | BO1: IgG2_A_Indonesia_05_2005_H5N1 | BP1: IgG2_A_Shanghai_1_2013_H7N9 | BQ1: IgG2_B_Phuket_3073_2013 | BR1: IgG2_B_Colorado_06_2017 | BS1: IgG2_B_Washington_02_2019 | BT1: IgG2_B_Austria_1359417_2021 | BU1: IgG2_Michigan_NA | BV1: IgG2_HongKong_NA | BW1: IgG2_Ebola | BX1: IgG2_RSV | BY1: IgG2_EBV | BZ1: IgG3_A_California_04_2009_H1N1 | CA1: IgG3_A_Michigan_45_2015_H1N1 | CB1: IgG3_A_Brisbane_02_2018_H1N1 | CC1: IgG3_A_Victoria_2570_2019_H1N1 | CD1: IgG3_A_Wisconsin_588_2019_H1N1 | CE1: IgG3_A_Hawaii_70_2019_H1N1 | CF1: IgG3_A_Wisconsin_67_2022_H1N1 | CG1: IgG3_A_HongKong_4801_2014_H3N2 | CH1: IgG3_A_Singapore_INFIMH16_2016_H3N2 | CI1: IgG3_A_Kansas_14_2017_H3N2 | CJ1: IgG3_A_HongKong_45_2019_H3N2 | CK1: IgG3_A_Cambodia_e0826360_2020_H3N2 | CL1: IgG3_A_Darwin_6_2021_H3N2 | CM1: IgG3_A_Indonesia_05_2005_H5N1 | CN1: IgG3_A_Shanghai_1_2013_H7N9 | CO1: IgG3_B_Phuket_3073_2013 | CP1: IgG3_B_Colorado_06_2017 | CQ1: IgG3_B_Washington_02_2019 | CR1: IgG3_B_Austria_1359417_2021 | CS1: IgG3_Michigan_NA | CT1: IgG3_HongKong_NA | CU1: IgG3_Ebola | CV1: IgG3_RSV | CW1: IgG3_EBV | CX1: IgG4_A_California_04_2009_H1N1 | CY1: IgG4_A_Michigan_45_2015_H1N1 | CZ1: IgG4_A_Brisbane_02_2018_H1N1 | DA1: IgG4_A_Victoria_2570_2019_H1N1 | DB1: IgG4_A_Wisconsin_588_2019_H1N1 | DC1: IgG4_A_Hawaii_70_2019_H1N1 | DD1: IgG4_A_Wisconsin_67_2022_H1N1 | DE1: IgG4_A_HongKong_4801_2014_H3N2 | DF1: IgG4_A_Singapore_INFIMH16_2016_H3N2 | DG1: IgG4_A_Kansas_14_2017_H3N2 | DH1: IgG4_A_HongKong_45_2019_H3N2 | DI1: IgG4_A_Cambodia_e0826360_2020_H3N2 | DJ1: IgG4_A_Darwin_6_2021_H3N2 | DK1: IgG4_A_Indonesia_05_2005_H5N1 | DL1: IgG4_A_Shanghai_1_2013_H7N9 | DM1: IgG4_B_Phuket_3073_2013 | DN1: IgG4_B_Colorado_06_2017 | DO1: IgG4_B_Washington_02_2019 | DP1: IgG4_B_Austria_1359417_2021 | DQ1: IgG4_Michigan_NA | DR1: IgG4_HongKong_NA | DS1: IgG4_Ebola | DT1: IgG4_RSV | DU1: IgG4_EBV | DV1: IgA1_A_California_04_2009_H1N1 | DW1: IgA1_A_Michigan_45_2015_H1N1 | DX1: IgA1_A_Brisbane_02_2018_H1N1 | DY1: IgA1_A_Victoria_2570_2019_H1N1 | DZ1: IgA1_A_Wisconsin_588_2019_H1N1 | EA1: IgA1_A_Hawaii_70_2019_H1N1 | EB1: IgA1_A_Wisconsin_67_2022_H1N1 | EC1: IgA1_A_HongKong_4801_2014_H3N2 | ED1: IgA1_A_Singapore_INFIMH16_2016_H3N2 | EE1: IgA1_A_Kansas_14_2017_H3N2 | EF1: IgA1_A_HongKong_45_2019_H3N2 | EG1: IgA1_A_Cambodia_e0826360_2020_H3N2 | EH1: IgA1_A_Darwin_6_2021_H3N2 | EI1: IgA1_A_Indonesia_05_2005_H5N1 | EJ1: IgA1_A_Shanghai_1_2013_H7N9 | EK1: IgA1_B_Phuket_3073_2013 | EL1: IgA1_B_Colorado_06_2017 | EM1: IgA1_B_Washington_02_2019 | EN1: IgA1_B_Austria_1359417_2021 | EO1: IgA1_Michigan_NA | EP1: IgA1_HongKong_NA | EQ1: IgA1_Ebola | ER1: IgA1_RSV | ES1: IgA1_EBV | ET1: IgA2_A_California_04_2009_H1N1 | EU1: IgA2_A_Michigan_45_2015_H1N1 | EV1: IgA2_A_Brisbane_02_2018_H1N1 | EW1: IgA2_A_Victoria_2570_2019_H1N1 | EX1: IgA2_A_Wisconsin_588_2019_H1N1 | EY1: IgA2_A_Hawaii_70_2019_H1N1 | EZ1: IgA2_A_Wisconsin_67_2022_H1N1 | FA1: IgA2_A_HongKong_4801_2014_H3N2 | FB1: IgA2_A_Singapore_INFIMH16_2016_H3N2 | FC1: IgA2_A_Kansas_14_2017_H3N2 | FD1: IgA2_A_HongKong_45_2019_H3N2 | FE1: IgA2_A_Cambodia_e0826360_2020_H3N2 | FF1: IgA2_A_Darwin_6_2021_H3N2 | FG1: IgA2_A_Indonesia_05_2005_H5N1 | FH1: IgA2_A_Shanghai_1_2013_H7N9 | FI1: IgA2_B_Phuket_3073_2013 | FJ1: IgA2_B_Colorado_06_2017 | FK1: IgA2_B_Washington_02_2019 | FL1: IgA2_B_Austria_1359417_2021 | FM1: IgA2_Michigan_NA | FN1: IgA2_HongKong_NA | FO1: IgA2_Ebola | FP1: IgA2_RSV | FQ1: IgA2_EBV | FR1: FcgR2A_A_California_04_2009_H1N1 | FS1: FcgR2A_A_Michigan_45_2015_H1N1 | FT1: FcgR2A_A_Brisbane_02_2018_H1N1 | FU1: FcgR2A_A_Victoria_2570_2019_H1N1 | FV1: FcgR2A_A_Wisconsin_588_2019_H1N1 | FW1: FcgR2A_A_Hawaii_70_2019_H1N1 | FX1: FcgR2A_A_Wisconsin_67_2022_H1N1 | FY1: FcgR2A_A_HongKong_4801_2014_H3N2 | FZ1: FcgR2A_A_Singapore_INFIMH16_2016_H3N2 | GA1: FcgR2A_A_Kansas_14_2017_H3N2 | GB1: FcgR2A_A_HongKong_45_2019_H3N2 | GC1: FcgR2A_A_Cambodia_e0826360_2020_H3N2 | GD1: FcgR2A_A_Darwin_6_2021_H3N2 | GE1: FcgR2A_A_Indonesia_05_2005_H5N1 | GF1: FcgR2A_A_Shanghai_1_2013_H7N9 | GG1: FcgR2A_B_Phuket_3073_2013 | GH1: FcgR2A_B_Colorado_06_2017 | GI1: FcgR2A_B_Washington_02_2019 | GJ1: FcgR2A_B_Austria_1359417_2021 | GK1: FcgR2A_Michigan_NA | GL1: FcgR2A_HongKong_NA | GM1: FcgR2A_Ebola | GN1: FcgR2A_RSV | GO1: FcgR2A_EBV | GP1: FcgR2B_A_California_04_2009_H1N1 | GQ1: FcgR2B_A_Michigan_45_2015_H1N1 | GR1: FcgR2B_A_Brisbane_02_2018_H1N1 | GS1: FcgR2B_A_Victoria_2570_2019_H1N1 | GT1: FcgR2B_A_Wisconsin_588_2019_H1N1 | GU1: FcgR2B_A_Hawaii_70_2019_H1N1 | GV1: FcgR2B_A_Wisconsin_67_2022_H1N1 | GW1: FcgR2B_A_HongKong_4801_2014_H3N2 | GX1: FcgR2B_A_Singapore_INFIMH16_2016_H3N2 | GY1: FcgR2B_A_Kansas_14_2017_H3N2 | GZ1: FcgR2B_A_HongKong_45_2019_H3N2 | HA1: FcgR2B_A_Cambodia_e0826360_2020_H3N2 | HB1: FcgR2B_A_Darwin_6_2021_H3N2 | HC1: FcgR2B_A_Indonesia_05_2005_H5N1 | HD1: FcgR2B_A_Shanghai_1_2013_H7N9 | HE1: FcgR2B_B_Phuket_3073_2013 | HF1: FcgR2B_B_Colorado_06_2017 | HG1: FcgR2B_B_Washington_02_2019 | HH1: FcgR2B_B_Austria_1359417_2021 | HI1: FcgR2B_Michigan_NA | HJ1: FcgR2B_HongKong_NA | HK1: FcgR2B_Ebola | HL1: FcgR2B_RSV | HM1: FcgR2B_EBV | HN1: FcgR3A_A_California_04_2009_H1N1 | HO1: FcgR3A_A_Michigan_45_2015_H1N1 | HP1: FcgR3A_A_Brisbane_02_2018_H1N1 | HQ1: FcgR3A_A_Victoria_2570_2019_H1N1 | HR1: FcgR3A_A_Wisconsin_588_2019_H1N1 | HS1: FcgR3A_A_Hawaii_70_2019_H1N1 | HT1: FcgR3A_A_Wisconsin_67_2022_H1N1 | HU1: FcgR3A_A_HongKong_4801_2014_H3N2 | HV1: FcgR3A_A_Singapore_INFIMH16_2016_H3N2 | HW1: FcgR3A_A_Kansas_14_2017_H3N2 | HX1: FcgR3A_A_HongKong_45_2019_H3N2 | HY1: FcgR3A_A_Cambodia_e0826360_2020_H3N2 | HZ1: FcgR3A_A_Darwin_6_2021_H3N2 | IA1: FcgR3A_A_Indonesia_05_2005_H5N1 | IB1: FcgR3A_A_Shanghai_1_2013_H7N9 | IC1: FcgR3A_B_Phuket_3073_2013 | ID1: FcgR3A_B_Colorado_06_2017 | IE1: FcgR3A_B_Washington_02_2019 | IF1: FcgR3A_B_Austria_1359417_2021 | IG1: FcgR3A_Michigan_NA | IH1: FcgR3A_HongKong_NA | II1: FcgR3A_Ebola | IJ1: FcgR3A_RSV | IK1: FcgR3A_EBV | IL1: FcgR3B_A_California_04_2009_H1N1 | IM1: FcgR3B_A_Michigan_45_2015_H1N1 | IN1: FcgR3B_A_Brisbane_02_2018_H1N1 | IO1: FcgR3B_A_Victoria_2570_2019_H1N1 | IP1: FcgR3B_A_Wisconsin_588_2019_H1N1 | IQ1: FcgR3B_A_Hawaii_70_2019_H1N1 | IR1: FcgR3B_A_Wisconsin_67_2022_H1N1 | IS1: FcgR3B_A_HongKong_4801_2014_H3N2 | IT1: FcgR3B_A_Singapore_INFIMH16_2016_H3N2 | IU1: FcgR3B_A_Kansas_14_2017_H3N2 | IV1: FcgR3B_A_HongKong_45_2019_H3N2 | IW1: FcgR3B_A_Cambodia_e0826360_2020_H3N2 | IX1: FcgR3B_A_Darwin_6_2021_H3N2 | IY1: FcgR3B_A_Indonesia_05_2005_H5N1 | IZ1: FcgR3B_A_Shanghai_1_2013_H7N9 | JA1: FcgR3B_B_Phuket_3073_2013 | JB1: FcgR3B_B_Colorado_06_2017 | JC1: FcgR3B_B_Washington_02_2019 | JD1: FcgR3B_B_Austria_1359417_2021 | JE1: FcgR3B_Michigan_NA | JF1: FcgR3B_HongKong_NA | JG1: FcgR3B_Ebola | JH1: FcgR3B_RSV | JI1: FcgR3B_EBV | JJ1: FcaR_A_California_04_2009_H1N1 | JK1: FcaR_A_Michigan_45_2015_H1N1 | JL1: FcaR_A_Brisbane_02_2018_H1N1 | JM1: FcaR_A_Victoria_2570_2019_H1N1 | JN1: FcaR_A_Wisconsin_588_2019_H1N1 | JO1: FcaR_A_Hawaii_70_2019_H1N1 | JP1: FcaR_A_Wisconsin_67_2022_H1N1 | JQ1: FcaR_A_HongKong_4801_2014_H3N2 | JR1: FcaR_A_Singapore_INFIMH16_2016_H3N2 | JS1: FcaR_A_Kansas_14_2017_H3N2 | JT1: FcaR_A_HongKong_45_2019_H3N2 | JU1: FcaR_A_Cambodia_e0826360_2020_H3N2 | JV1: FcaR_A_Darwin_6_2021_H3N2 | JW1: FcaR_A_Indonesia_05_2005_H5N1 | JX1: FcaR_A_Shanghai_1_2013_H7N9 | JY1: FcaR_B_Phuket_3073_2013 | JZ1: FcaR_B_Colorado_06_2017 | KA1: FcaR_B_Washington_02_2019 | KB1: FcaR_B_Austria_1359417_2021 | KC1: FcaR_Michigan_NA | KD1: FcaR_HongKong_NA | KE1: FcaR_Ebola | KF1: FcaR_RSV | KG1: FcaR_EBV | KH1: ADCD_A_California_04_2009_H1N1 | KI1: ADCD_A_Michigan_45_2015_H1N1 | KJ1: ADCD_A_Brisbane_02_2018_H1N1 | KK1: ADCD_A_Victoria_2570_2019_H1N1 | KL1: ADCD_A_Wisconsin_588_2019_H1N1 | KM1: ADCD_A_Hawaii_70_2019_H1N1 | KN1: ADCD_A_Wisconsin_67_2022_H1N1 | KO1: ADCD_A_HongKong_4801_2014_H3N2 | KP1: ADCD_A_Singapore_INFIMH16_2016_H3N2 | KQ1: ADCD_A_Kansas_14_2017_H3N2 | KR1: ADCD_A_HongKong_45_2019_H3N2 | KS1: ADCD_A_Cambodia_e0826360_2020_H3N2 | KT1: ADCD_A_Darwin_6_2021_H3N2 | KU1: ADCD_A_Indonesia_05_2005_H5N1 | KV1: ADCD_A_Shanghai_1_2013_H7N9 | KW1: ADCD_B_Phuket_3073_2013 | KX1: ADCD_B_Colorado_06_2017 | KY1: ADCD_B_Washington_02_2019 | KZ1: ADCD_B_Austria_1359417_2021 | LA1: ADCD_Michigan_NA | LB1: ADCD_HongKong_NA | LC1: ADCD_Ebola | LD1: ADCD_RSV | LE1: ADCD_EBV | LF1: ADNP_A_California_04_2009_H1N1 | LG1: ADNP_A_HongKong_4801_2014_H3N2 | LH1: ADNP_B_Phuket_3073_2013 | LI1: ADCP_A_California_04_2009_H1N1 | LJ1: ADCP_A_HongKong_4801_2014_H3N2 | LK1: ADCP_B_Phuket_3073_2013
A2: CC0023 | B2: 227773 | C2: 2.5714286 | D2: 1 | E2: 5 | F2: 373.94922 | G2: 561.81005 | H2: 485.83886 | I2: 534.21387 | J2: 391.01464 | K2: 498.23633 | L2: 448.08349 | M2: 695.12158 | N2: 639.04151 | O2: 582.60255 | P2: 485.73486 | Q2: 611.88281 | R2: 931.4341 | S2: 112.62207 | T2: 285.5708 | U2: 709.69582 | V2: 609.81396 | W2: 694.68212 | X2: 430.5918 | Y2: 467.90723 | Z2: 374.42774 | AA2: 837.93506 | AB2: 808.66063 | AC2: 402.35303 | AD2: 0.968265 | AE2: 0.84424 | AF2: 0 | AG2: 0 | AH2: 0 | AI2: 4.486815 | AJ2: 0 | AK2: 55.237795 | AL2: 6.143065 | AM2: 143.12011 | AN2: 263.49903 | AO2: 0 | AP2: 23.377445 | AQ2: 0 | AR2: 0 | AS2: 5.457515 | AT2: 0.55713 | AU2: 0 | AV2: 0.41456 | AW2: 0 | AX2: 53.315915 | AY2: 7.57275 | AZ2: 0 | BA2: 8.83008 | BB2: 10.104 | BC2: 4.05615 | BD2: 10.569825 | BE2: 0 | BF2: 0 | BG2: 11.188965 | BH2: 0 | BI2: 40.91992 | BJ2: 6.24463 | BK2: 19.6499 | BL2: 58.07373 | BM2: 0 | BN2: 16.928705 | BO2: 0 | BP2: 13.754885 | BQ2: 14.79346 | BR2: 0 | BS2: 0 | BT2: 10.381345 | BU2: 9.502445 | BV2: 7.929685 | BW2: 4.145025 | BX2: 2.913575 | BY2: 7.2959 | BZ2: 2.631345 | CA2: 1.072265 | CB2: 0 | CC2: 0 | CD2: 0 | CE2: 5.19092 | CF2: 0 | CG2: 0 | CH2: 5.965815 | CI2: 15.29639 | CJ2: 2.260735 | CK2: 0 | CL2: 19.586915 | CM2: 0 | CN2: 0 | CO2: 0 | CP2: 4.445315 | CQ2: 0 | CR2: 0 | CS2: 0 | CT2: 10.54541 | CU2: 8.34521 | CV2: 0.17822 | CW2: 9.35498 | CX2: 164.35498 | CY2: 66.194825 | CZ2: 24.500005 | DA2: 44.77197 | DB2: 51.548345 | DC2: 40.72168 | DD2: 72.184085 | DE2: 24.49267 | DF2: 26.247555 | DG2: 9.08057 | DH2: 35.33985 | DI2: 16.27099 | DJ2: 25.747555 | DK2: 0 | DL2: 40.2417 | DM2: 19.48437 | DN2: 56.80811 | DO2: 71.05078 | DP2: 57.96045 | DQ2: 8.972655 | DR2: 6.901365 | DS2: 2.03662 | DT2: 1.322755 | DU2: 2.959965 | DV2: 5863.6029 | DW2: 3190.3725 | DX2: 1347.226 | DY2: 2126.3813 | DZ2: 2219.9839 | EA2: 3174.8066 | EB2: 1789.4922 | EC2: 982.96191 | ED2: 157.15381 | EE2: 848.58447 | EF2: 1705.7705 | EG2: 307.19629 | EH2: 452.70605 | EI2: 8.17627 | EJ2: 311.34375 | EK2: 1367.0606 | EL2: 170.42139 | EM2: 338.04737 | EN2: 145.46777 | EO2: 254.1919 | EP2: 135.09668 | EQ2: 134.17188 | ER2: 1060.3482 | ES2: 82.98633 | ET2: 2915.9306 | EU2: 928.6831 | EV2: 209.99756 | EW2: 573.12697 | EX2: 596.46875 | EY2: 1230.852 | EZ2: 235.14404 | FA2: 185.77295 | FB2: 13.734375 | FC2: 181.44775 | FD2: 341.83007 | FE2: 22.263185 | FF2: 79.305175 | FG2: 0 | FH2: 23.494145 | FI2: 430.83936 | FJ2: 0 | FK2: 13.14551 | FL2: 11.11377 | FM2: 31.97363 | FN2: 31.756835 | FO2: 189.01709 | FP2: 700.56836 | FQ2: 48.637205 | FR2: 6824.4385 | FS2: 2962.2183 | FT2: 183.8877 | FU2: 6658.5215 | FV2: 6284.8833 | FW2: 3115.3999 | FX2: 0 | FY2: 12642.171 | FZ2: 1049.9262 | GA2: 0 | GB2: 16409.928 | GC2: 1491.8315 | GD2: 4084.333 | GE2: 0 | GF2: 0 | GG2: 6279.9644 | GH2: 0 | GI2: 3361.1645 | GJ2: 5498.1934 | GK2: 0 | GL2: 2231.2119 | GM2: 11.54394 | GN2: 2803.7764 | GO2: 4559.8281 | GP2: 4102.6846 | GQ2: 802.07277 | GR2: 14.20068 | GS2: 2643.1743 | GT2: 2658.1821 | GU2: 827.56984 | GV2: 0 | GW2: 10075.593 | GX2: 258.19678 | GY2: 219.5129 | GZ2: 16356.18 | HA2: 137.42383 | HB2: 2351.0825 | HC2: 0 | HD2: 0 | HE2: 4436.4726 | HF2: 0 | HG2: 743.47411 | HH2: 2214.8784 | HI2: 0 | HJ2: 358.17138 | HK2: 10.623045 | HL2: 1863.3667 | HM2: 549.99365 | HN2: 3524.8262 | HO2: 673.47999 | HP2: 39.149415 | HQ2: 2139.2998 | HR2: 2105.2974 | HS2: 1230.3628 | HT2: 0 | HU2: 6507.773 | HV2: 745.27197 | HW2: 0 | HX2: 11306.834 | HY2: 421.82911 | HZ2: 265.25586 | IA2: 0 | IB2: 0 | IC2: 4076.9546 | ID2: 0 | IE2: 690.79297 | IF2: 1530.1455 | IG2: 0 | IH2: 98.66748 | II2: 10.029785 | IJ2: 2151.2969 | IK2: 292.22901 | IL2: 1142.75 | IM2: 12.592285 | IN2: 0 | IO2: 214.56641 | IP2: 246.47119 | IQ2: 49.07764 | IR2: 0 | IS2: 4301.958 | IT2: 26.294925 | IU2: 0 | IV2: 12538.564 | IW2: 0 | IX2: 53.94287 | IY2: 0 | IZ2: 0 | JA2: 3456.4253 | JB2: 0 | JC2: 11.98242 | JD2: 122.21484 | JE2: 0 | JF2: 29.06348 | JG2: 4.308105 | JH2: 463.69726 | JI2: 27.317875 | JJ2: 5029.1304 | JK2: 2933.8301 | JL2: 1219.3052 | JM2: 2732.4028 | JN2: 2719.5517 | JO2: 3151.6103 | JP2: 0 | JQ2: 911.94385 | JR2: 148.98047 | JS2: 0 | JT2: 1450.9434 | JU2: 127.71386 | JV2: 230.59326 | JW2: 0 | JX2: 277.40771 | JY2: 2343.4223 | JZ2: 0 | KA2: 508.12988 | KB2: 86.00879 | KC2: 165.99024 | KD2: 87.43945 | KE2: 88.265625 | KF2: 700.87404 | KG2: 1.905275 | KH2: 0 | KI2: 532.5 | KJ2: 0 | KK2: 1157 | KL2: 1106.5 | KM2: 0 | KN2: 0 | KO2: 6543.5 | KP2: 298.75 | KQ2: 6611.5 | KR2: 1137 | KS2: 1187.5 | KT2: 310201.25 | KU2: 0 | KV2: 0 | KW2: 17875 | KX2: 2309.25 | KY2: 1782.5 | KZ2: 607.75 | LA2: 0 | LB2: 0 | LC2: 0 | LD2: 0 | LE2: 28281.5 | LF2: 0 | LG2: 2874.7565 | LH2: 0 | LI2: 213.76198 | LJ2: 666.03904 | LK2: 0
A3: CC0023 | B3: 234552 | C3: 7.2857143 | D3: 2 | E3: 5 | F3: 193.10156 | G3: 206.79932 | H3: 195.57763 | I3: 210.60547 | J3: 184.88623 | K3: 235.67872 | L3: 211.94922 | M3: 405.13966 | N3: 322.35595 | O3: 224.01416 | P3: 227.01416 | Q3: 254.02588 | R3: 307.04981 | S3: 35.947265 | T3: 135.1753 | U3: 327.51075 | V3: 235.00878 | W3: 282.56054 | X3: 231.66456 | Y3: 294.79834 | Z3: 193.85693 | AA3: 432.29296 | AB3: 429.94921 | AC3: 284.9253 | AD3: 31.96631 | AE3: 19.894045 | AF3: 8.31885 | AG3: 30.67627 | AH3: 34.293945 | AI3: 33.015625 | AJ3: 17.00488 | AK3: 220.24511 | AL3: 21.486815 | AM3: 269.72363 | AN3: 406.27246 | AO3: 11.870605 | AP3: 89.43262 | AQ3: 0 | AR3: 0 | AS3: 254.40234 | AT3: 61.496585 | AU3: 16.118655 | AV3: 38.601565 | AW3: 0 | AX3: 54.08008 | AY3: 8.342285 | AZ3: 171.27735 | BA3: 22.308105 | BB3: 8.725095 | BC3: 6.52295 | BD3: 10.36523 | BE3: 0 | BF3: 0 | BG3: 9.96728 | BH3: 0 | BI3: 69.34473 | BJ3: 4.44775 | BK3: 34.59033 | BL3: 66.098145 | BM3: 0 | BN3: 17.577145 | BO3: 0 | BP3: 10.234375 | BQ3: 13.271485 | BR3: 0.296385 | BS3: 0 | BT3: 12.82959 | BU3: 11.88428 | BV3: 12.331545 | BW3: 9.30371 | BX3: 6.629395 | BY3: 9.15918 | BZ3: 2.171875 | CA3: 1.5542 | CB3: 0 | CC3: 0 | CD3: 0 | CE3: 4.94922 | CF3: 0.29639 | CG3: 0 | CH3: 5.537595 | CI3: 14.51563 | CJ3: 2.4082 | CK3: 0 | CL3: 19.1626 | CM3: 0 | CN3: 0 | CO3: 0.265135 | CP3: 2.82129 | CQ3: 0 | CR3: 0.186035 | CS3: 0 | CT3: 9.911625 | CU3: 7.471675 | CV3: 2.814455 | CW3: 8.221685 | CX3: 209.00586 | CY3: 91.11572 | CZ3: 26.566895 | DA3: 47.7373 | DB3: 52.425295 | DC3: 46.632325 | DD3: 75.90283 | DE3: 35.792475 | DF3: 33.45898 | DG3: 9.596195 | DH3: 44.45899 | DI3: 15.637205 | DJ3: 19.52343 | DK3: 0 | DL3: 52.849125 | DM3: 28.74072 | DN3: 70.9292 | DO3: 77.832035 | DP3: 70.55957 | DQ3: 6.804685 | DR3: 5.581545 | DS3: 1.475585 | DT3: 1.785645 | DU3: 0.957525 | DV3: 4859.1421 | DW3: 2669.314 | DX3: 1090.7544 | DY3: 1812.9292 | DZ3: 1932.3193 | EA3: 2501.6699 | EB3: 1355.062 | EC3: 1009.5444 | ED3: 172.11279 | EE3: 1152.8628 | EF3: 1690.98 | EG3: 423.20654 | EH3: 584.71923 | EI3: 9.11572 | EJ3: 248.72607 | EK3: 1188.4072 | EL3: 234.9917 | EM3: 306.41943 | EN3: 156.25244 | EO3: 218.58642 | EP3: 124.54687 | EQ3: 124.07519 | ER3: 2591.9409 | ES3: 299.99462 | ET3: 1743.315 | EU3: 473.68212 | EV3: 113.91162 | EW3: 317.97412 | EX3: 332.72412 | EY3: 728.65282 | EZ3: 94.98193 | FA3: 176.74219 | FB3: 18.84766 | FC3: 151.5459 | FD3: 273.2456 | FE3: 26.8794 | FF3: 100.23437 | FG3: 6.48584 | FH3: 11.79883 | FI3: 288.82129 | FJ3: 0 | FK3: 8.9043 | FL3: 13.208005 | FM3: 20.904785 | FN3: 36.41211 | FO3: 116.3457 | FP3: 1034.4619 | FQ3: 82.00781 | FR3: 7730.7847 | FS3: 3866.3599 | FT3: 518.95069 | FU3: 7065.059 | FV3: 6538.2247 | FW3: 4247.5079 | FX3: 0 | FY3: 13036.282 | FZ3: 1199.3393 | GA3: 0 | GB3: 17565.341 | GC3: 2336.7749 | GD3: 4500.498 | GE3: 0 | GF3: 0 | GG3: 7636.2905 | GH3: 0 | GI3: 4709.6909 | GJ3: 6397.1525 | GK3: 0 | GL3: 2356.938 | GM3: 10.93213 | GN3: 4569.6967 | GO3: 5137.8091 | GP3: 5010.3443 | GQ3: 1117.7896 | GR3: 19.748045 | GS3: 3124.3632 | GT3: 3146.3745 | GU3: 1487.688 | GV3: 0 | GW3: 11004.208 | GX3: 450.72314 | GY3: 986.79165 | GZ3: 15839.365 | HA3: 342.80176 | HB3: 2334.5264 | HC3: 0 | HD3: 0 | HE3: 6618.3794 | HF3: 0 | HG3: 1658.2818 | HH3: 2967.0547 | HI3: 0 | HJ3: 536.28368 | HK3: 8.549315 | HL3: 3419.1268 | HM3: 1082.0098 | HN3: 4244.0512 | HO3: 913.93653 | HP3: 94.89551 | HQ3: 2648.0157 | HR3: 2714.2339 | HS3: 2007.8267 | HT3: 0 | HU3: 7964.0577 | HV3: 1458.8804 | HW3: 0 | HX3: 11957.965 | HY3: 761.07421 | HZ3: 322.52686 | IA3: 0 | IB3: 7.781255 | IC3: 7259.789 | ID3: 0 | IE3: 1539.1064 | IF3: 2479.9453 | IG3: 0 | IH3: 105.52783 | II3: 11.004395 | IJ3: 4264.7793 | IK3: 694.16699 | IL3: 2483.9624 | IM3: 42.5166 | IN3: 4.10107 | IO3: 631.54345 | IP3: 603.73144 | IQ3: 446.37842 | IR3: 0 | IS3: 7640.9712 | IT3: 144.27002 | IU3: 0 | IV3: 14412.556 | IW3: 20.12744 | IX3: 62.81738 | IY3: 0 | IZ3: 0 | JA3: 8358.7469 | JB3: 0 | JC3: 140.33154 | JD3: 549.36816 | JE3: 0 | JF3: 41.81104 | JG3: 7.40625 | JH3: 2693.691 | JI3: 152.79395 | JJ3: 5269.9526 | JK3: 2967.3106 | JL3: 1277.1098 | JM3: 2733.9346 | JN3: 2729.1708 | JO3: 3041.5537 | JP3: 0 | JQ3: 1261.0977 | JR3: 429.61913 | JS3: 0 | JT3: 1970.77 | JU3: 392.98438 | JV3: 398.29834 | JW3: 0 | JX3: 431.92138 | JY3: 4256.1626 | JZ3: 0 | KA3: 596.28955 | KB3: 192.18604 | KC3: 196.63086 | KD3: 94.2998 | KE3: 101.62207 | KF3: 2609.0655 | KG3: 170.39111 | KH3: 0 | KI3: 0 | KJ3: 2088.25 | KK3: 1729.5 | KL3: 2109.5 | KM3: 51 | KN3: 0 | KO3: 11624.25 | KP3: 2983.75 | KQ3: 5010.75 | KR3: 8751.5 | KS3: 649.5 | KT3: 264365.75 | KU3: 0 | KV3: 0 | KW3: 11177 | KX3: 3556.5 | KY3: 896.5 | KZ3: 597 | LA3: 0 | LB3: 0 | LC3: 0 | LD3: 8667.75 | LE3: 20045.75 | LF3: 0 | LG3: 2483.3643 | LH3: 0 | LI3: 273.8121 | LJ3: 604.32649 | LK3: 0
A4: CC0023 | B4: 270607 | C4: 28.428571 | D4: 3 | E4: 5 | F4: 158.37011 | G4: 181.53125 | H4: 175.52685 | I4: 136.56054 | J4: 206.13623 | K4: 208.61573 | L4: 167.44727 | M4: 314.47753 | N4: 211.27881 | O4: 234.45947 | P4: 206.99365 | Q4: 302.4834 | R4: 224.51417 | S4: 34.00879 | T4: 146.04493 | U4: 279.91309 | V4: 158.3252 | W4: 186.03857 | X4: 208.04834 | Y4: 184.52686 | Z4: 140.2041 | AA4: 363.86377 | AB4: 324.53711 | AC4: 214.92627 | AD4: 43.09473 | AE4: 18.933595 | AF4: 9.48584 | AG4: 34.67627 | AH4: 31.88672 | AI4: 49.46582 | AJ4: 20.2041 | AK4: 101.54102 | AL4: 12.35547 | AM4: 97.16797 | AN4: 222.71485 | AO4: 7.39014 | AP4: 84.72559 | AQ4: 0 | AR4: 0 | AS4: 158.60351 | AT4: 42.69678 | AU4: 13.16699 | AV4: 24.90186 | AW4: 0 | AX4: 52.705075 | AY4: 8.99902 | AZ4: 68.586425 | BA4: 21.089355 | BB4: 6.2207 | BC4: 5.625485 | BD4: 7.765135 | BE4: 0 | BF4: 0 | BG4: 7.640135 | BH4: 0 | BI4: 22.149415 | BJ4: 1.30908 | BK4: 18.078125 | BL4: 21.90967 | BM4: 0 | BN4: 20.637695 | BO4: 0 | BP4: 11.025885 | BQ4: 15.51416 | BR4: 0 | BS4: 0 | BT4: 19.26172 | BU4: 12.86377 | BV4: 14.61865 | BW4: 9.50342 | BX4: 6.39453 | BY4: 4.858395 | BZ4: 1.555175 | CA4: 1.248535 | CB4: 0 | CC4: 0 | CD4: 0 | CE4: 4.721675 | CF4: 0 | CG4: 0.139645 | CH4: 4.760255 | CI4: 14.937505 | CJ4: 1.648435 | CK4: 0 | CL4: 19.231445 | CM4: 0 | CN4: 0 | CO4: 0 | CP4: 3.167965 | CQ4: 0 | CR4: 0.229495 | CS4: 0 | CT4: 9.8418 | CU4: 6.380855 | CV4: 0 | CW4: 10.67432 | CX4: 82.13037 | CY4: 55.10205 | CZ4: 19.50684 | DA4: 15.08496 | DB4: 9.73389 | DC4: 21.05371 | DD4: 22.087405 | DE4: 22.229975 | DF4: 19.44531 | DG4: 8.0791 | DH4: 23.617195 | DI4: 13.555665 | DJ4: 19.08447 | DK4: 0 | DL4: 31.800295 | DM4: 20.497555 | DN4: 38.02539 | DO4: 40.53955 | DP4: 41.621585 | DQ4: 7.719725 | DR4: 6.396485 | DS4: 2.99316 | DT4: 2.699705 | DU4: 1.060545 | DV4: 3209.79 | DW4: 1832.3184 | DX4: 709.07471 | DY4: 994.72756 | DZ4: 960.52344 | EA4: 1504.0669 | EB4: 653.73437 | EC4: 757.4746 | ED4: 97.37353 | EE4: 584.39257 | EF4: 1352.5239 | EG4: 304.0503 | EH4: 310.63233 | EI4: 0.177245 | EJ4: 160.33594 | EK4: 770.74219 | EL4: 145.68213 | EM4: 173.35449 | EN4: 103.46729 | EO4: 187.48535 | EP4: 97.52734 | EQ4: 89.46533 | ER4: 1130.646 | ES4: 90.64844 | ET4: 1293.0196 | EU4: 308.71387 | EV4: 64.532715 | EW4: 140.46777 | EX4: 127.67725 | EY4: 376.98632 | EZ4: 11.040525 | FA4: 137.81739 | FB4: 10.175785 | FC4: 83.520995 | FD4: 209.68945 | FE4: 16.76221 | FF4: 51.615235 | FG4: 0 | FH4: 3.480475 | FI4: 172.19678 | FJ4: 0 | FK4: 3.42334 | FL4: 7.29346 | FM4: 14.492185 | FN4: 31.856445 | FO4: 82.41406 | FP4: 410.74903 | FQ4: 32.55371 | FR4: 5800.2451 | FS4: 2705.0493 | FT4: 160.78565 | FU4: 3322.185 | FV4: 3083.3696 | FW4: 2062.8066 | FX4: 0 | FY4: 12011.256 | FZ4: 1081.5264 | GA4: 0 | GB4: 16150.807 | GC4: 1077.8257 | GD4: 3136.457 | GE4: 0 | GF4: 0 | GG4: 7083.5195 | GH4: 0 | GI4: 3397.5938 | GJ4: 4823.81 | GK4: 0 | GL4: 1118.4116 | GM4: 12.08105 | GN4: 4292.3695 | GO4: 5571.2431 | GP4: 2607.2798 | GQ4: 539.68408 | GR4: 5.27685 | GS4: 899.92626 | GT4: 837.62205 | GU4: 361.39649 | GV4: 0 | GW4: 10479.304 | GX4: 282.91944 | GY4: 0 | GZ4: 16795.651 | HA4: 90.61133 | HB4: 1987.5244 | HC4: 0 | HD4: 0 | HE4: 6727.2168 | HF4: 0 | HG4: 897.02002 | HH4: 2150.0161 | HI4: 0 | HJ4: 80.906245 | HK4: 7.16455 | HL4: 3501.4951 | HM4: 1563.5713 | HN4: 2693.3315 | HO4: 335.77099 | HP4: 22.842775 | HQ4: 1100.0508 | HR4: 894.09425 | HS4: 958.07813 | HT4: 0 | HU4: 7117.5607 | HV4: 434.00196 | HW4: 0 | HX4: 11033.935 | HY4: 284.52441 | HZ4: 145.09717 | IA4: 0 | IB4: 0 | IC4: 7259.0279 | ID4: 0 | IE4: 830.58302 | IF4: 1551.6387 | IG4: 0 | IH4: 60.36377 | II4: 11.029295 | IJ4: 3903.2588 | IK4: 608.24659 | IL4: 361.43359 | IM4: 1.95459 | IN4: 0 | IO4: 28.93066 | IP4: 19.541015 | IQ4: 34.616705 | IR4: 0 | IS4: 4292.3423 | IT4: 14.70117 | IU4: 0 | IV4: 12222.035 | IW4: 0 | IX4: 38.96094 | IY4: 0 | IZ4: 0 | JA4: 8165.0607 | JB4: 0 | JC4: 15.947265 | JD4: 125.74267 | JE4: 0 | JF4: 20.136725 | JG4: 6.61133 | JH4: 1082.0312 | JI4: 56.158205 | JJ4: 3715.2089 | JK4: 1833.4053 | JL4: 633.5249 | JM4: 1400.2915 | JN4: 1342.126 | JO4: 1737.124 | JP4: 0 | JQ4: 787.91697 | JR4: 101.21679 | JS4: 0 | JT4: 1389.0137 | JU4: 180.78173 | JV4: 175.40283 | JW4: 0 | JX4: 135.9873 | JY4: 4343.5062 | JZ4: 0 | KA4: 187.62646 | KB4: 87.105465 | KC4: 158.88672 | KD4: 49.13574 | KE4: 60.381345 | KF4: 922.07227 | KG4: 12.026855 | KH4: 0 | KI4: 0 | KJ4: 0 | KK4: 359.5 | KL4: 630.25 | KM4: 0 | KN4: 0 | KO4: 4560.75 | KP4: 0 | KQ4: 2290 | KR4: 0 | KS4: 634 | KT4: 204861.5 | KU4: 0 | KV4: 0 | KW4: 6615.5 | KX4: 415 | KY4: 0 | KZ4: 0 | LA4: 0 | LB4: 0 | LC4: 0 | LD4: 0 | LE4: 11523.75 | LF4: 881.41802 | LG4: 4064.3708 | LH4: 0 | LI4: 137.1523 | LJ4: 335.77587 | LK4: 0
A5: CC0037 | B5: 227682 | C5: 2.7142857 | D5: 1 | E5: 5 | F5: 71.865235 | G5: 80.05713 | H5: 79.54492 | I5: 70.6748 | J5: 46.880375 | K5: 84.371095 | L5: 67.025875 | M5: 172.49023 | N5: 131.49414 | O5: 81.57178 | P5: 73.60986 | Q5: 109.19727 | R5: 100.72168 | S5: 5.969725 | T5: 64.891115 | U5: 127.22608 | V5: 57.63623 | W5: 102.95606 | X5: 96.70801 | Y5: 120.99171 | Z5: 119.07422 | AA5: 144.27588 | AB5: 137.26122 | AC5: 130.63818 | AD5: 1078.3682 | AE5: 426.0708 | AF5: 154.89307 | AG5: 844.70799 | AH5: 861.43456 | AI5: 1119.3496 | AJ5: 296.82959 | AK5: 288.375 | AL5: 41.214845 | AM5: 274.88524 | AN5: 91.9668 | AO5: 25.14404 | AP5: 88.54736 | AQ5: 3.83252 | AR5: 0.154785 | AS5: 389.34911 | AT5: 116.93945 | AU5: 70.88135 | AV5: 85.77198 | AW5: 0 | AX5: 84.91113 | AY5: 8.043455 | AZ5: 333.86329 | BA5: 79.100585 | BB5: 1.145505 | BC5: 1.03369 | BD5: 6.84766 | BE5: 0 | BF5: 0 | BG5: 4.55029 | BH5: 0 | BI5: 1.83643 | BJ5: 1.097165 | BK5: 0.25537 | BL5: 6.314945 | BM5: 0 | BN5: 13.59277 | BO5: 0 | BP5: 11.40918 | BQ5: 11.71973 | BR5: 0 | BS5: 0 | BT5: 9.879885 | BU5: 7.541505 | BV5: 9.95703 | BW5: 4.944825 | BX5: 21.250975 | BY5: 6.738275 | BZ5: 54.591795 | CA5: 38.81885 | CB5: 23.342775 | CC5: 52.48633 | CD5: 55.050775 | CE5: 49.938965 | CF5: 37.79395 | CG5: 21.20312 | CH5: 11.970215 | CI5: 25.77344 | CJ5: 9.87646 | CK5: 2.340825 | CL5: 32.905275 | CM5: 0 | CN5: 0 | CO5: 4.884275 | CP5: 3.87695 | CQ5: 0 | CR5: 2.739745 | CS5: 0 | CT5: 11.068365 | CU5: 6.690915 | CV5: 0.22412 | CW5: 9.1084 | CX5: 0.437985 | CY5: 0 | CZ5: 0 | DA5: 0 | DB5: 0 | DC5: 4.88574 | DD5: 0 | DE5: 0 | DF5: 8.46191 | DG5: 1.399905 | DH5: 1.746585 | DI5: 4.2583 | DJ5: 12.51269 | DK5: 0 | DL5: 8.20752 | DM5: 8.146485 | DN5: 3.806155 | DO5: 0 | DP5: 8.674315 | DQ5: 11.708985 | DR5: 7.92871 | DS5: 1.32129 | DT5: 3.111815 | DU5: 2.782225 | DV5: 6783.8466 | DW5: 4067.6167 | DX5: 2683.604 | DY5: 6795.9101 | DZ5: 7069.48 | EA5: 7089.1145 | EB5: 6244.9557 | EC5: 5990.5641 | ED5: 1329.1309 | EE5: 8619.9623 | EF5: 9335.436 | EG5: 8220.7011 | EH5: 10100.871 | EI5: 633.46241 | EJ5: 367.10645 | EK5: 7933.6308 | EL5: 5120.4658 | EM5: 5800.5415 | EN5: 3577.8584 | EO5: 173.70947 | EP5: 158.83642 | EQ5: 443.51758 | ER5: 5326.836 | ES5: 364.79053 | ET5: 3281.9498 | EU5: 1014.3037 | EV5: 546.31592 | EW5: 2967.7876 | EX5: 2889.0796 | EY5: 3465.5478 | EZ5: 2274.2919 | FA5: 2725.96 | FB5: 198.64941 | FC5: 4560.0961 | FD5: 6535.4189 | FE5: 5362.9526 | FF5: 7715.5322 | FG5: 17.744625 | FH5: 16.869145 | FI5: 4527.8041 | FJ5: 1954.1075 | FK5: 2004.9067 | FL5: 876.14795 | FM5: 5.927245 | FN5: 49.609865 | FO5: 157.29444 | FP5: 1913.71 | FQ5: 63.577145 | FR5: 12125.24 | FS5: 11605.101 | FT5: 8612.8726 | FU5: 14318.521 | FV5: 14266.336 | FW5: 12885.346 | FX5: 7995.093 | FY5: 9769.9337 | FZ5: 1390.019 | GA5: 0 | GB5: 2744.6533 | GC5: 1288.6074 | GD5: 1171.5972 | GE5: 0 | GF5: 0 | GG5: 6524.4608 | GH5: 0 | GI5: 6327.9073 | GJ5: 5590.639 | GK5: 0 | GL5: 1995.5278 | GM5: 8.50244 | GN5: 6097.299 | GO5: 10362.382 | GP5: 13520.22 | GQ5: 8929.2326 | GR5: 5507.0039 | GS5: 13783.746 | GT5: 13844.569 | GU5: 13609.669 | GV5: 5827.8331 | GW5: 6923.6226 | GX5: 189.27246 | GY5: 0 | GZ5: 176.52295 | HA5: 70.524905 | HB5: 172.29883 | HC5: 0 | HD5: 0 | HE5: 5443.2256 | HF5: 0 | HG5: 2883.1079 | HH5: 2700.397 | HI5: 0 | HJ5: 110.58886 | HK5: 8.277345 | HL5: 4943.5101 | HM5: 5538.0674 | HN5: 11039.481 | HO5: 6921.798 | HP5: 4066.5956 | HQ5: 10698.675 | HR5: 9940.5174 | HS5: 10901.776 | HT5: 497.46123 | HU5: 5892.4847 | HV5: 824.92187 | HW5: 0 | HX5: 1003.6387 | HY5: 520.31592 | HZ5: 1055.2832 | IA5: 50.033695 | IB5: 23.00733 | IC5: 4412.5489 | ID5: 0 | IE5: 2575.0171 | IF5: 2799.021 | IG5: 0 | IH5: 116.93506 | II5: 9.69971 | IJ5: 5492.3945 | IK5: 4958.7079 | IL5: 11887.379 | IM5: 7385.283 | IN5: 4425.0874 | IO5: 11134.505 | IP5: 11264.482 | IQ5: 11901.047 | IR5: 989.30695 | IS5: 5137.3315 | IT5: 67.813475 | IU5: 0 | IV5: 84.70166 | IW5: 24.17041 | IX5: 181.8667 | IY5: 0 | IZ5: 0 | JA5: 3536.1201 | JB5: 0 | JC5: 702.49853 | JD5: 859.67629 | JE5: 0 | JF5: 57.24756 | JG5: 10.74463 | JH5: 3804.67 | JI5: 4003.1699 | JJ5: 5746.6001 | JK5: 3611.4493 | JL5: 2784.7954 | JM5: 6578.0089 | JN5: 6402.7403 | JO5: 6580.1074 | JP5: 738.46841 | JQ5: 4912.6597 | JR5: 1516.7432 | JS5: 0 | JT5: 7524.9977 | JU5: 7066.1152 | JV5: 5335.0425 | JW5: 811.74315 | JX5: 557.74707 | JY5: 6708.1138 | JZ5: 0 | KA5: 5565.4898 | KB5: 3512.6259 | KC5: 59.77246 | KD5: 105.70703 | KE5: 177.5498 | KF5: 5274.0723 | KG5: 232.15527 | KH5: 239065.25 | KI5: 1001.75 | KJ5: 2007.25 | KK5: 17140 | KL5: 15398.75 | KM5: 111304.25 | KN5: 3060.25 | KO5: 3323 | KP5: 2550 | KQ5: 2206.5 | KR5: 0 | KS5: 26.75 | KT5: 1042.25 | KU5: 0 | KV5: 0 | KW5: 5855.25 | KX5: 1367.5 | KY5: 1017.25 | KZ5: 363.25 | LA5: 0 | LB5: 0 | LC5: 0 | LD5: 7456.25 | LE5: 16149.75 | LF5: 431.07715 | LG5: 3617.7949 | LH5: 0 | LI5: 1594.0051 | LJ5: 5.9333957 | LK5: 0
A6: CC0037 | B6: 234930 | C6: 7.8571429 | D6: 2 | E6: 5 | F6: 113.28711 | G6: 127.51075 | H6: 136.72314 | I6: 104.92578 | J6: 96.83838 | K6: 106.69287 | L6: 79.85693 | M6: 319.75928 | N6: 120.39356 | O6: 134.36524 | P6: 148.96729 | Q6: 106.75 | R6: 170.06592 | S6: 5.404295 | T6: 107.60352 | U6: 204.65723 | V6: 122.29736 | W6: 192.44531 | X6: 202.41651 | Y6: 146.10449 | Z6: 135.64404 | AA6: 215.90577 | AB6: 245.46143 | AC6: 176.05225 | AD6: 1182.041 | AE6: 872.56152 | AF6: 404.90528 | AG6: 716.54492 | AH6: 708.67578 | AI6: 544.72752 | AJ6: 303.58105 | AK6: 344.55371 | AL6: 104.99512 | AM6: 294.0879 | AN6: 373.33106 | AO6: 103.49267 | AP6: 383.47901 | AQ6: 38.640135 | AR6: 36.76367 | AS6: 3421.44 | AT6: 1125.9678 | AU6: 296.07031 | AV6: 334.55713 | AW6: 10.506835 | AX6: 63.41748 | AY6: 8.66601 | AZ6: 6487.3463 | BA6: 70.754885 | BB6: 4.208985 | BC6: 4.17285 | BD6: 5.43164 | BE6: 0 | BF6: 0 | BG6: 6.463865 | BH6: 0 | BI6: 5.677245 | BJ6: 0 | BK6: 0 | BL6: 5.484375 | BM6: 0 | BN6: 16.86767 | BO6: 0 | BP6: 10.47168 | BQ6: 16.044925 | BR6: 0 | BS6: 0 | BT6: 11.43164 | BU6: 10.50879 | BV6: 14.834475 | BW6: 9.336915 | BX6: 35.589355 | BY6: 6.89306 | BZ6: 15.679685 | CA6: 8.308105 | CB6: 3.645015 | CC6: 8.217775 | CD6: 8.398435 | CE6: 14.73291 | CF6: 7.84424 | CG6: 2.562495 | CH6: 6.019525 | CI6: 17.102055 | CJ6: 4.685055 | CK6: 0 | CL6: 22.435545 | CM6: 0 | CN6: 0 | CO6: 0.793945 | CP6: 1.697265 | CQ6: 0 | CR6: 1.10791 | CS6: 0 | CT6: 9.77344 | CU6: 7.91992 | CV6: 1.45996 | CW6: 8.666015 | CX6: 0 | CY6: 0 | CZ6: 2.12061 | DA6: 0 | DB6: 0 | DC6: 5.22656 | DD6: 0 | DE6: 0 | DF6: 4.987795 | DG6: 2.540525 | DH6: 1.911135 | DI6: 4.514645 | DJ6: 11.84033 | DK6: 0 | DL6: 8.14209 | DM6: 6.79687 | DN6: 4.058105 | DO6: 0 | DP6: 11.42529 | DQ6: 8.092285 | DR6: 6.572265 | DS6: 2.34961 | DT6: 4.297365 | DU6: 5.070315 | DV6: 2135.8174 | DW6: 859.27978 | DX6: 743.94384 | DY6: 1082.8906 | DZ6: 1110.1729 | EA6: 1373.168 | EB6: 1062.5679 | EC6: 2799.1616 | ED6: 555.14796 | EE6: 2549.2652 | EF6: 4281.2202 | EG6: 3099.5102 | EH6: 5433.5478 | EI6: 109.59619 | EJ6: 300.16895 | EK6: 3584.0654 | EL6: 1305.2876 | EM6: 2812.3374 | EN6: 712.91601 | EO6: 101.40185 | EP6: 106.68066 | EQ6: 152.63281 | ER6: 2635.686 | ES6: 171.12988 | ET6: 438.47706 | EU6: 70.91992 | EV6: 95.271975 | EW6: 112.54297 | EX6: 110.94336 | EY6: 183.57617 | EZ6: 59.330565 | FA6: 853.0791 | FB6: 194.06592 | FC6: 717.43359 | FD6: 1330.4053 | FE6: 846.6753 | FF6: 2683.2637 | FG6: 0 | FH6: 33.90723 | FI6: 1143.2793 | FJ6: 123.64063 | FK6: 601.76953 | FL6: 70.540525 | FM6: 9.5332 | FN6: 33.5083 | FO6: 120.13575 | FP6: 1183.2949 | FQ6: 84.295895 | FR6: 13397.472 | FS6: 9960.1371 | FT6: 6541.6089 | FU6: 13080.396 | FV6: 13190.726 | FW6: 12275.565 | FX6: 6978.5655 | FY6: 8301.6487 | FZ6: 520.17385 | GA6: 0 | GB6: 4548.5274 | GC6: 1830.9272 | GD6: 805.90282 | GE6: 0 | GF6: 0 | GG6: 9179.2015 | GH6: 611.147 | GI6: 5014.4903 | GJ6: 4796.9633 | GK6: 0 | GL6: 374.09864 | GM6: 10.9458 | GN6: 13665.939 | GO6: 6206.169 | GP6: 12858.82 | GQ6: 8002.1021 | GR6: 4337.5606 | GS6: 11025.088 | GT6: 10511.65 | GU6: 10856.82 | GV6: 4060.4496 | GW6: 5546.7447 | GX6: 34.223145 | GY6: 0 | GZ6: 1879.3774 | HA6: 286.34571 | HB6: 226.74854 | HC6: 0 | HD6: 0 | HE6: 10936.696 | HF6: 1510.0044 | HG6: 2413.9731 | HH6: 2662.4312 | HI6: 0 | HJ6: 0 | HK6: 10.875485 | HL6: 19074.581 | HM6: 2251.7954 | HN6: 9736.2741 | HO6: 5156.332 | HP6: 2715.7202 | HQ6: 7577.75 | HR6: 7977.6699 | HS6: 8999.7082 | HT6: 0 | HU6: 4876.94 | HV6: 385.13085 | HW6: 0 | HX6: 2604.6856 | HY6: 769.46973 | HZ6: 332.88477 | IA6: 105.646 | IB6: 42.06006 | IC6: 8276.4417 | ID6: 0 | IE6: 1964.4287 | IF6: 2299.8081 | IG6: 0 | IH6: 46.998045 | II6: 14.4541 | IJ6: 16142.58 | IK6: 4714.1362 | IL6: 11794.482 | IM6: 3674.3076 | IN6: 817.97069 | IO6: 6823.662 | IP6: 6758.211 | IQ6: 9801.3374 | IR6: 0 | IS6: 2973.1128 | IT6: 30.855955 | IU6: 0 | IV6: 530.57178 | IW6: 40.41943 | IX6: 70.67578 | IY6: 0 | IZ6: 0.03564 | JA6: 9963.1405 | JB6: 0 | JC6: 212.89893 | JD6: 419.3501 | JE6: 0 | JF6: 21.792485 | JG6: 11.558595 | JH6: 18410.294 | JI6: 3278.8408 | JJ6: 2299.7378 | JK6: 737.31445 | JL6: 876.35448 | JM6: 1475.5977 | JN6: 1407.4556 | JO6: 1935.4131 | JP6: 0 | JQ6: 2434.2886 | JR6: 726.89942 | JS6: 0 | JT6: 4271.9679 | JU6: 3297.8945 | JV6: 3632.9136 | JW6: 7.45117 | JX6: 238.38135 | JY6: 7352.2832 | JZ6: 0 | KA6: 3489.5395 | KB6: 767.08641 | KC6: 20.09375 | KD6: 35.770015 | KE6: 87.523925 | KF6: 2535.3716 | KG6: 35.569335 | KH6: 0 | KI6: 1694 | KJ6: 5494.75 | KK6: 1758 | KL6: 2484 | KM6: 23.75 | KN6: 0 | KO6: 5540 | KP6: 3084.75 | KQ6: 4172.5 | KR6: 0 | KS6: 427.25 | KT6: 20154.75 | KU6: 0 | KV6: 0 | KW6: 7249.25 | KX6: 6848 | KY6: 445.5 | KZ6: 1982.25 | LA6: 2915.75 | LB6: 0 | LC6: 0 | LD6: 170764.5 | LE6: 15098.25 | LF6: 0 | LG6: 3002.5486 | LH6: 0 | LI6: 924.03527 | LJ6: 227.13376 | LK6: 0
A7: CC0037 | B7: 236578 | C7: 9.8571429 | D7: 2 | E7: 5 | F7: 121.77051 | G7: 160.06006 | H7: 158.16699 | I7: 102.32129 | J7: 122.61181 | K7: 175.49415 | L7: 122.97314 | M7: 252.73974 | N7: 189.53564 | O7: 180.43018 | P7: 136.11084 | Q7: 243.40381 | R7: 223.04835 | S7: 18.264645 | T7: 111.61719 | U7: 238.83008 | V7: 181.6333 | W7: 227.63183 | X7: 212.94531 | Y7: 223.45947 | Z7: 270.33008 | AA7: 368.50244 | AB7: 268.87696 | AC7: 183.50439 | AD7: 846.54784 | AE7: 201.04102 | AF7: 88.88721 | AG7: 426.78174 | AH7: 407.99365 | AI7: 664.78859 | AJ7: 198.80761 | AK7: 59.04199 | AL7: 12.0376 | AM7: 63.977045 | AN7: 8.783205 | AO7: 0 | AP7: 20.46143 | AQ7: 0 | AR7: 0 | AS7: 23.15625 | AT7: 6.479005 | AU7: 0 | AV7: 3.92725 | AW7: 0 | AX7: 76.274905 | AY7: 8.02734 | AZ7: 43.671385 | BA7: 30.04053 | BB7: 2.86621 | BC7: 5.224605 | BD7: 8.174315 | BE7: 0 | BF7: 0 | BG7: 7.066895 | BH7: 0 | BI7: 10.324705 | BJ7: 0.92041 | BK7: 1.176265 | BL7: 9.052735 | BM7: 0 | BN7: 19.39892 | BO7: 0 | BP7: 12.201175 | BQ7: 15.482915 | BR7: 0 | BS7: 0 | BT7: 14.369135 | BU7: 17.09424 | BV7: 17.285155 | BW7: 7.28418 | BX7: 44.55713 | BY7: 9.217775 | BZ7: 47.107425 | CA7: 27.8291 | CB7: 15.749505 | CC7: 34.245605 | CD7: 37.16601 | CE7: 39.882325 | CF7: 31.93897 | CG7: 17.52685 | CH7: 10.758785 | CI7: 23.348635 | CJ7: 9.91015 | CK7: 1.24219 | CL7: 27.946285 | CM7: 0 | CN7: 0 | CO7: 9.28613 | CP7: 4.262695 | CQ7: 0 | CR7: 3.07666 | CS7: 0 | CT7: 12.541995 | CU7: 8.59668 | CV7: 1.539065 | CW7: 9.73291 | CX7: 0.103025 | CY7: 0.42578 | CZ7: 3.289555 | DA7: 0 | DB7: 0 | DC7: 5.62842 | DD7: 0 | DE7: 1.423825 | DF7: 6.96582 | DG7: 1.977055 | DH7: 0.89942 | DI7: 3.982415 | DJ7: 10.359375 | DK7: 0 | DL7: 6.431155 | DM7: 8.174805 | DN7: 2.745605 | DO7: 0 | DP7: 9.595215 | DQ7: 8.463865 | DR7: 7.795895 | DS7: 0.81445 | DT7: 5.17725 | DU7: 4.560055 | DV7: 3679.2548 | DW7: 2421.521 | DX7: 1201.6308 | DY7: 3896.6289 | DZ7: 3743.6426 | EA7: 4031.1289 | EB7: 3091.5639 | EC7: 3931.7749 | ED7: 695.99951 | EE7: 5171.2817 | EF7: 7364.5745 | EG7: 7207.0073 | EH7: 9069.3143 | EI7: 308.43994 | EJ7: 95.970705 | EK7: 6799.3536 | EL7: 3343.7544 | EM7: 3672.1216 | EN7: 2182.2832 | EO7: 119.13379 | EP7: 60.99072 | EQ7: 282.8999 | ER7: 2979.4648 | ES7: 231.52685 | ET7: 1808.7739 | EU7: 542.64453 | EV7: 169.06836 | EW7: 1491.1567 | EX7: 1342.3921 | EY7: 1709.6763 | EZ7: 876.34424 | FA7: 1807.2442 | FB7: 87.60547 | FC7: 3680.019 | FD7: 5498.0488 | FE7: 4997.2207 | FF7: 7461.8139 | FG7: 1.140625 | FH7: 0 | FI7: 4147.5059 | FJ7: 990.31496 | FK7: 1305.5507 | FL7: 546.72363 | FM7: 2.190425 | FN7: 17.79492 | FO7: 101.16797 | FP7: 1033.5996 | FQ7: 57.375975 | FR7: 14406.013 | FS7: 13412.777 | FT7: 10763.926 | FU7: 16311.526 | FV7: 15833.2 | FW7: 15755.809 | FX7: 10598.012 | FY7: 10979.274 | FZ7: 2188.1807 | GA7: 0 | GB7: 3227.2143 | GC7: 1828.2681 | GD7: 1167.6997 | GE7: 0 | GF7: 0 | GG7: 5960.5945 | GH7: 204.78809 | GI7: 6493.272 | GJ7: 6012.9365 | GK7: 0 | GL7: 1447.6338 | GM7: 13.20312 | GN7: 6934.751 | GO7: 12166.641 | GP7: 15453.778 | GQ7: 11052.799 | GR7: 6463.2212 | GS7: 15086.143 | GT7: 15342.568 | GU7: 14843.381 | GV7: 8639.4456 | GW7: 7776.0229 | GX7: 167.2998 | GY7: 0 | GZ7: 244.78174 | HA7: 83.78955 | HB7: 123.45703 | HC7: 0 | HD7: 0 | HE7: 4319.518 | HF7: 0 | HG7: 2422.1733 | HH7: 2013.9199 | HI7: 0 | HJ7: 6.05859 | HK7: 6.526855 | HL7: 4602.3365 | HM7: 8253.1137 | HN7: 11795.885 | HO7: 8529.8693 | HP7: 4621.9199 | HQ7: 11471.665 | HR7: 11605.172 | HS7: 12175.366 | HT7: 1556.8407 | HU7: 6313.1231 | HV7: 357.09326 | HW7: 0 | HX7: 1096.3242 | HY7: 586.98535 | HZ7: 851.51121 | IA7: 15.866215 | IB7: 6.4751 | IC7: 4438.894 | ID7: 0 | IE7: 2347.9497 | IF7: 1871.1885 | IG7: 0 | IH7: 35.21631 | II7: 9.17871 | IJ7: 4192.8624 | IK7: 5861.2041 | IL7: 14470.782 | IM7: 9866.1454 | IN7: 5013.1606 | IO7: 14288.136 | IP7: 14184.744 | IQ7: 14271.161 | IR7: 3542.9354 | IS7: 5979.997 | IT7: 23.306155 | IU7: 0 | IV7: 69.15332 | IW7: 13.248535 | IX7: 141.29834 | IY7: 0 | IZ7: 0 | JA7: 4421.9688 | JB7: 0 | JC7: 626.01806 | JD7: 517.90478 | JE7: 0 | JF7: 30.187015 | JG7: 8.52637 | JH7: 2779.1596 | JI7: 5884.5996 | JJ7: 2901.6865 | JK7: 1916.6197 | JL7: 1110.0947 | JM7: 3530.5458 | JN7: 3591.1924 | JO7: 3518.3047 | JP7: 0 | JQ7: 2780.3843 | JR7: 405.98974 | JS7: 0 | JT7: 5384.5752 | JU7: 4917.8887 | JV7: 3914.1538 | JW7: 247.37646 | JX7: 52.835445 | JY7: 5392.7797 | JZ7: 0 | KA7: 3169.3374 | KB7: 1831.8418 | KC7: 24.959475 | KD7: 23.98828 | KE7: 77.97314 | KF7: 2314.3599 | KG7: 71.30957 | KH7: 316546 | KI7: 2682.75 | KJ7: 5640.25 | KK7: 13199.5 | KL7: 12532.5 | KM7: 63216.25 | KN7: 2854.25 | KO7: 4287.5 | KP7: 2304 | KQ7: 2494.5 | KR7: 0 | KS7: 276 | KT7: 250.5 | KU7: 0 | KV7: 0 | KW7: 8401.25 | KX7: 4148 | KY7: 1459 | KZ7: 1723.25 | LA7: 1583.5 | LB7: 0 | LC7: 0 | LD7: 8499 | LE7: 23318.75 | LF7: 0 | LG7: 1245.4154 | LH7: 0 | LI7: 1165.5799 | LJ7: 456.53145 | LK7: 0
A8: CC0037 | B8: 282172 | C8: 31.571429 | D8: 3 | E8: 5 | F8: 82.712405 | G8: 83.29932 | H8: 86.84619 | I8: 53.453615 | J8: 62.3667 | K8: 53.391605 | L8: 61.674805 | M8: 116.90966 | N8: 78.708495 | O8: 83.44971 | P8: 61.856935 | Q8: 80.61377 | R8: 86.099615 | S8: 2.779785 | T8: 71.61426 | U8: 194.19287 | V8: 69.42236 | W8: 78.524415 | X8: 67.891115 | Y8: 107.84376 | Z8: 85.71094 | AA8: 144.35156 | AB8: 111.80322 | AC8: 88.80859 | AD8: 233.69775 | AE8: 82.730955 | AF8: 41.204595 | AG8: 170.16015 | AH8: 182.62695 | AI8: 274.39062 | AJ8: 64.73535 | AK8: 41.089355 | AL8: 11.973145 | AM8: 29.21533 | AN8: 11.990725 | AO8: 0.19336 | AP8: 21.352055 | AQ8: 0 | AR8: 0 | AS8: 54.185545 | AT8: 19.1792 | AU8: 7.996095 | AV8: 15.03809 | AW8: 0 | AX8: 52.64453 | AY8: 9.390135 | AZ8: 29.607905 | BA8: 60.243655 | BB8: 4.90039 | BC8: 1.61621 | BD8: 5.501465 | BE8: 0 | BF8: 0 | BG8: 6.541505 | BH8: 0 | BI8: 8.21094 | BJ8: 0 | BK8: 0 | BL8: 4.234375 | BM8: 0 | BN8: 14.284175 | BO8: 0 | BP8: 8.223635 | BQ8: 13.41895 | BR8: 0.71289 | BS8: 0 | BT8: 13.44238 | BU8: 8.857915 | BV8: 11.47949 | BW8: 23.796385 | BX8: 26.53125 | BY8: 5.02832 | BZ8: 26.05957 | CA8: 15.50488 | CB8: 8.630855 | CC8: 19.4292 | CD8: 21.446285 | CE8: 27.00977 | CF8: 17.14893 | CG8: 13.682125 | CH8: 10.015625 | CI8: 20.22559 | CJ8: 7.940425 | CK8: 0.02637 | CL8: 26.367675 | CM8: 0 | CN8: 0 | CO8: 9.0083 | CP8: 4.00098 | CQ8: 0 | CR8: 2.571775 | CS8: 0 | CT8: 11.93653 | CU8: 11.37988 | CV8: 1.37451 | CW8: 10.29688 | CX8: 0 | CY8: 0 | CZ8: 0.10694 | DA8: 0 | DB8: 0 | DC8: 3.86328 | DD8: 0 | DE8: 0 | DF8: 6.322755 | DG8: 1.15918 | DH8: 1.059085 | DI8: 4.09863 | DJ8: 9.066895 | DK8: 0 | DL8: 9.111325 | DM8: 3.231445 | DN8: 3.58252 | DO8: 0 | DP8: 7.913575 | DQ8: 7.46045 | DR8: 6.30176 | DS8: 6.347165 | DT8: 4.030765 | DU8: 2.99414 | DV8: 3957.8666 | DW8: 2141.1694 | DX8: 1093.8706 | DY8: 3473.9297 | DZ8: 3694.8184 | EA8: 3317.1499 | EB8: 2482.7808 | EC8: 3974.2139 | ED8: 580.12647 | EE8: 8164.1203 | EF8: 9330.8425 | EG8: 7683.0187 | EH8: 9848.1693 | EI8: 240.73779 | EJ8: 64.02344 | EK8: 7407.2735 | EL8: 3023.1416 | EM8: 3495.1455 | EN8: 2400.3784 | EO8: 153.44239 | EP8: 65.58789 | EQ8: 359.13135 | ER8: 3638.0376 | ES8: 428.1792 | ET8: 1558.3936 | EU8: 431.6997 | EV8: 117.57374 | EW8: 1328.0259 | EX8: 1389.3472 | EY8: 1285.7105 | EZ8: 542.84034 | FA8: 1572.5073 | FB8: 72.595705 | FC8: 4939.3276 | FD8: 6114.6294 | FE8: 4642.0131 | FF8: 7814.0176 | FG8: 0 | FH8: 0 | FI8: 4686.1915 | FJ8: 873.25928 | FK8: 1062.6572 | FL8: 614.89941 | FM8: 2.67285 | FN8: 17.19727 | FO8: 120.83398 | FP8: 1155.3305 | FQ8: 65.74951 | FR8: 14120.771 | FS8: 11694.42 | FT8: 8009.2419 | FU8: 15582.398 | FV8: 15307.895 | FW8: 14251.622 | FX8: 9488.7115 | FY8: 9541.9002 | FZ8: 497.3413 | GA8: 0 | GB8: 2655.8447 | GC8: 1092.9829 | GD8: 629.94093 | GE8: 0 | GF8: 0 | GG8: 5114.5537 | GH8: 0 | GI8: 3694.4229 | GJ8: 2648.9682 | GK8: 0 | GL8: 566.00682 | GM8: 12.76709 | GN8: 5544.0715 | GO8: 13540.689 | GP8: 14274.163 | GQ8: 9670.6386 | GR8: 5182.4474 | GS8: 13924.688 | GT8: 13865.851 | GU8: 13884.748 | GV8: 6737.2061 | GW8: 6111.5009 | GX8: 9.500975 | GY8: 0 | GZ8: 156.88428 | HA8: 22.66992 | HB8: 29.528805 | HC8: 0 | HD8: 0 | HE8: 2729.3759 | HF8: 0 | HG8: 861.60987 | HH8: 343.99757 | HI8: 0 | HJ8: 0 | HK8: 8.20996 | HL8: 3879.3458 | HM8: 11340.802 | HN8: 9592.0041 | HO8: 6484.6391 | HP8: 3143.6245 | HQ8: 9718.6696 | HR8: 9441.6514 | HS8: 10184.766 | HT8: 0 | HU8: 4342.7623 | HV8: 31.969725 | HW8: 0 | HX8: 725.61425 | HY8: 272.58155 | HZ8: 375.25586 | IA8: 0 | IB8: 0 | IC8: 2560.124 | ID8: 0 | IE8: 865.43165 | IF8: 606.79736 | IG8: 0 | IH8: 35.845705 | II8: 9.12451 | IJ8: 2931.3433 | IK8: 6585.0146 | IL8: 11750.632 | IM8: 6381.5362 | IN8: 1507.5532 | IO8: 11332.932 | IP8: 11102.109 | IQ8: 12422.873 | IR8: 0 | IS8: 2932.6856 | IT8: 8.02051 | IU8: 0 | IV8: 41.783205 | IW8: 0.02734 | IX8: 69.624025 | IY8: 0 | IZ8: 0 | JA8: 2139.21 | JB8: 0 | JC8: 67.67578 | JD8: 39.752435 | JE8: 0 | JF8: 19.694825 | JG8: 8.1958 | JH8: 1555.3062 | JI8: 7668.8257 | JJ8: 3739.605 | JK8: 2086.6577 | JL8: 923.6499 | JM8: 4199.452 | JN8: 3943.8271 | JO8: 4206.0074 | JP8: 0 | JQ8: 3230.1075 | JR8: 154.58155 | JS8: 0 | JT8: 7826.1548 | JU8: 7445.7295 | JV8: 5539.7225 | JW8: 201.68847 | JX8: 0 | JY8: 7287.3463 | JZ8: 0 | KA8: 3883.8941 | KB8: 2134.7954 | KC8: 28.67578 | KD8: 24.617675 | KE8: 115.71631 | KF8: 3011.9873 | KG8: 211.24413 | KH8: 2357 | KI8: 0 | KJ8: 0 | KK8: 364 | KL8: 677.5 | KM8: 472.5 | KN8: 0 | KO8: 0 | KP8: 0 | KQ8: 470.25 | KR8: 0 | KS8: 0 | KT8: 1914.25 | KU8: 0 | KV8: 0 | KW8: 1552.75 | KX8: 0 | KY8: 0 | KZ8: 0 | LA8: 0 | LB8: 0 | LC8: 0 | LD8: 0 | LE8: 10875.75 | LF8: 491.38436 | LG8: 4443.8919 | LH8: 0 | LI8: 1461.8267 | LJ8: 303.81644 | LK8: 0
A9: CC0051 | B9: 237846 | C9: 7.4285714 | D9: 2 | E9: 1 | F9: 972.86671 | G9: 1602.6738 | H9: 1818.9634 | I9: 934.15332 | J9: 1193.1738 | K9: 1339.6167 | L9: 923.44433 | M9: 2699.3618 | N9: 1274.9375 | O9: 1993.9575 | P9: 1638.2071 | Q9: 1687.6651 | R9: 3620.4198 | S9: 227.03125 | T9: 568.37159 | U9: 2631.3834 | V9: 1764.0893 | W9: 2316.4912 | X9: 1758.6773 | Y9: 1809.6568 | Z9: 1135.9458 | AA9: 3167.1567 | AB9: 1842.3491 | AC9: 1846.1172 | AD9: 1380.1401 | AE9: 782.77831 | AF9: 256.40771 | AG9: 485.43554 | AH9: 522.74803 | AI9: 369.01172 | AJ9: 385.31739 | AK9: 5544.6738 | AL9: 1378.5552 | AM9: 3063.2299 | AN9: 3654.0264 | AO9: 1403.6826 | AP9: 2076.5532 | AQ9: 109.22119 | AR9: 249.0586 | AS9: 3130.0005 | AT9: 1748.8467 | AU9: 1145.1011 | AV9: 1018.8521 | AW9: 0 | AX9: 609.75879 | AY9: 29.35205 | AZ9: 4917.5123 | BA9: 468.77198 | BB9: 39.2251 | BC9: 49.29199 | BD9: 51.378905 | BE9: 16.750005 | BF9: 26.977045 | BG9: 51.816895 | BH9: 31.895505 | BI9: 92.032225 | BJ9: 61.069335 | BK9: 53.535155 | BL9: 37.591795 | BM9: 46.455075 | BN9: 117.07715 | BO9: 0 | BP9: 42.620605 | BQ9: 116.26563 | BR9: 52.445795 | BS9: 58.512205 | BT9: 59.043945 | BU9: 62.839845 | BV9: 78.606445 | BW9: 93.441405 | BX9: 24.808595 | BY9: 51.398435 | BZ9: 5.885255 | CA9: 9.16211 | CB9: 4.08203 | CC9: 2.476075 | CD9: 5.3247 | CE9: 9.200195 | CF9: 4.37598 | CG9: 18.337885 | CH9: 12.384275 | CI9: 20.4126 | CJ9: 11.471675 | CK9: 3.174315 | CL9: 34.21875 | CM9: 0 | CN9: 0 | CO9: 13.057615 | CP9: 6.368165 | CQ9: 0 | CR9: 4.152345 | CS9: 0 | CT9: 9.286625 | CU9: 9.214355 | CV9: 122.50097 | CW9: 10.0376 | CX9: 0 | CY9: 0 | CZ9: 2.8501 | DA9: 0 | DB9: 0 | DC9: 4.68164 | DD9: 0 | DE9: 0 | DF9: 5.23779 | DG9: 2.010255 | DH9: 1.13477 | DI9: 2.364255 | DJ9: 12.869135 | DK9: 0 | DL9: 7.458495 | DM9: 8.730465 | DN9: 2.4458 | DO9: 0 | DP9: 8.188475 | DQ9: 7.31055 | DR9: 5.515625 | DS9: 0.84033 | DT9: 0.970215 | DU9: 1.161135 | DV9: 2121.565 | DW9: 655.73974 | DX9: 229.08252 | DY9: 686.90917 | DZ9: 746.7788 | EA9: 613.9121 | EB9: 1181.6768 | EC9: 1762.0635 | ED9: 88.64404 | EE9: 1051.7304 | EF9: 896.5923 | EG9: 592.87059 | EH9: 611.09816 | EI9: 73.138185 | EJ9: 134.50146 | EK9: 1248.5596 | EL9: 340.21289 | EM9: 391.16943 | EN9: 419.83155 | EO9: 424.43994 | EP9: 705.6328 | EQ9: 673.98193 | ER9: 8790.362 | ES9: 2619.0405 | ET9: 1619.0064 | EU9: 207.89502 | EV9: 43.212405 | EW9: 176.41016 | EX9: 179.57568 | EY9: 134.03418 | EZ9: 320.19579 | FA9: 603.59718 | FB9: 22.882815 | FC9: 275.80127 | FD9: 245.18164 | FE9: 149.34961 | FF9: 169.66943 | FG9: 20.73291 | FH9: 26.24658 | FI9: 569.92382 | FJ9: 23.07764 | FK9: 70.444825 | FL9: 81.51367 | FM9: 128.47071 | FN9: 350.60596 | FO9: 274.66162 | FP9: 6682.2119 | FQ9: 5449.496 | FR9: 5612.634 | FS9: 4719.9741 | FT9: 397.92725 | FU9: 933.89015 | FV9: 684.45266 | FW9: 1298.3594 | FX9: 0 | FY9: 9881.5117 | FZ9: 1263.3955 | GA9: 0 | GB9: 8480.3623 | GC9: 4033.397 | GD9: 7796.4225 | GE9: 0 | GF9: 0 | GG9: 6464.48 | GH9: 0 | GI9: 5226.458 | GJ9: 3573.484 | GK9: 0 | GL9: 1067.565 | GM9: 23.62256 | GN9: 2807.1806 | GO9: 1881.5425 | GP9: 2172.5825 | GQ9: 1284.9321 | GR9: 9.242185 | GS9: 101.2666 | GT9: 13.004395 | GU9: 135.2036 | GV9: 0 | GW9: 7284.5611 | GX9: 178.40185 | GY9: 0 | GZ9: 5548.7729 | HA9: 976.26952 | HB9: 2904.9638 | HC9: 0 | HD9: 0 | HE9: 4403.0205 | HF9: 0 | HG9: 1805.7193 | HH9: 1081.9975 | HI9: 0 | HJ9: 3.974605 | HK9: 15.65381 | HL9: 1504.1934 | HM9: 94.92285 | HN9: 2842.2417 | HO9: 1897.0269 | HP9: 116.10693 | HQ9: 962.89163 | HR9: 1076.7627 | HS9: 1665.7075 | HT9: 0 | HU9: 4841.8872 | HV9: 318.35059 | HW9: 0 | HX9: 4123.2353 | HY9: 1192.5591 | HZ9: 961.47216 | IA9: 42.87989 | IB9: 233.92334 | IC9: 6421.5933 | ID9: 0 | IE9: 3252.3335 | IF9: 2567.7666 | IG9: 0 | IH9: 78.435545 | II9: 16.79199 | IJ9: 1975.1284 | IK9: 548.20459 | IL9: 2074.3208 | IM9: 682.97655 | IN9: 12.121095 | IO9: 111.5708 | IP9: 123.13818 | IQ9: 424.92773 | IR9: 0 | IS9: 4987.0386 | IT9: 22.214845 | IU9: 0 | IV9: 3416.7652 | IW9: 133.99902 | IX9: 204.68311 | IY9: 0 | IZ9: 0 | JA9: 9151.4345 | JB9: 0 | JC9: 1449.0825 | JD9: 888.41651 | JE9: 0 | JF9: 26.405765 | JG9: 9.75537 | JH9: 521.96533 | JI9: 56.78223 | JJ9: 684.82321 | JK9: 195.32763 | JL9: 53.63867 | JM9: 268.30663 | JN9: 318.65918 | JO9: 253.03809 | JP9: 0 | JQ9: 402.48291 | JR9: 31.560545 | JS9: 0 | JT9: 354.4834 | JU9: 122.7749 | JV9: 309.48925 | JW9: 0 | JX9: 0 | JY9: 3541.3384 | JZ9: 0 | KA9: 63.80078 | KB9: 96.271485 | KC9: 58.87256 | KD9: 67.207515 | KE9: 64.10742 | KF9: 2506.6763 | KG9: 889.45116 | KH9: 0 | KI9: 485.5 | KJ9: 796.25 | KK9: 9725.5 | KL9: 9691 | KM9: 1939.75 | KN9: 3298 | KO9: 5493 | KP9: 56.5 | KQ9: 9930.75 | KR9: 1055 | KS9: 1648.75 | KT9: 408538.5 | KU9: 0 | KV9: 0 | KW9: 24120 | KX9: 2361.75 | KY9: 681.25 | KZ9: 303.5 | LA9: 0 | LB9: 0 | LC9: 0 | LD9: 0 | LE9: 5083.5 | LF9: 1215.2866 | LG9: 3563.0785 | LH9: 39.75372 | LI9: 91.52625 | LJ9: 900.06415 | LK9: 0
A10: CC0051 | B10: 230544 | C10: 54.428571 | D10: 3 | E10: 1 | F10: 401.57421 | G10: 355.60254 | H10: 516.06346 | I10: 374.53077 | J10: 250.74658 | K10: 607.72069 | L10: 455.95801 | M10: 890.39158 | N10: 577.68457 | O10: 418.26611 | P10: 403.99756 | Q10: 659.89795 | R10: 701.90038 | S10: 45.602535 | T10: 297.17285 | U10: 653.76172 | V10: 376.35205 | W10: 577.57519 | X10: 522.63917 | Y10: 359.88086 | Z10: 482.89941 | AA10: 943.16162 | AB10: 637.25878 | AC10: 611.37208 | AD10: 132.68262 | AE10: 64.93213 | AF10: 23.70069 | AG10: 71.74756 | AH10: 79.998535 | AI10: 52.723145 | AJ10: 38.242185 | AK10: 401.14941 | AL10: 64.84326 | AM10: 310.80273 | AN10: 442.99316 | AO10: 92.392575 | AP10: 271.55713 | AQ10: 0.751465 | AR10: 5.86133 | AS10: 410.78418 | AT10: 111.59913 | AU10: 41.677245 | AV10: 61.305665 | AW10: 0 | AX10: 78.17334 | AY10: 12.09814 | AZ10: 541.86963 | BA10: 38.017575 | BB10: 3.91992 | BC10: 3.281245 | BD10: 9.42578 | BE10: 0 | BF10: 0 | BG10: 7.726075 | BH10: 0 | BI10: 4.28467 | BJ10: 1.139645 | BK10: 0.937495 | BL10: 3.46338 | BM10: 0 | BN10: 18.197265 | BO10: 0 | BP10: 11.73633 | BQ10: 11.57276 | BR10: 0 | BS10: 0 | BT10: 9.20068 | BU10: 7.83496 | BV10: 7.95166 | BW10: 4.42041 | BX10: 0 | BY10: 7.1206 | BZ10: 2.21826 | CA10: 2.04004 | CB10: 0 | CC10: 0 | CD10: 0 | CE10: 6.064455 | CF10: 0 | CG10: 0.387695 | CH10: 6.03955 | CI10: 14.82422 | CJ10: 1.861815 | CK10: 0 | CL10: 19.5 | CM10: 0 | CN10: 0 | CO10: 0.9834 | CP10: 1.94824 | CQ10: 0 | CR10: 0.696775 | CS10: 0 | CT10: 9.32959 | CU10: 8.946775 | CV10: 6.531245 | CW10: 9.3169 | CX10: 0 | CY10: 0 | CZ10: 1.314945 | DA10: 0 | DB10: 0 | DC10: 3.694335 | DD10: 0 | DE10: 0 | DF10: 4.332515 | DG10: 0.76221 | DH10: 1.07813 | DI10: 2.758785 | DJ10: 11.119625 | DK10: 0 | DL10: 6.650875 | DM10: 6.762695 | DN10: 1.59375 | DO10: 0 | DP10: 6.956545 | DQ10: 5.45508 | DR10: 6.33594 | DS10: 0.660155 | DT10: 1.44092 | DU10: 0 | DV10: 1078.7671 | DW10: 316.50635 | DX10: 232.4292 | DY10: 442.84278 | DZ10: 482.12061 | EA10: 320.62451 | EB10: 634.91163 | EC10: 760.00536 | ED10: 254.27734 | EE10: 719.24659 | EF10: 637.00291 | EG10: 368.37793 | EH10: 608.54199 | EI10: 21.945805 | EJ10: 75.36914 | EK10: 578.13574 | EL10: 239.44776 | EM10: 197.92432 | EN10: 203.1084 | EO10: 124.60889 | EP10: 420.59766 | EQ10: 243.29492 | ER10: 11440.152 | ES10: 638.74804 | ET10: 324.54931 | EU10: 48.53906 | EV10: 40.27832 | EW10: 49.39453 | EX10: 50.606445 | EY10: 37.685055 | EZ10: 33.90283 | FA10: 141.14014 | FB10: 108.11768 | FC10: 92.598635 | FD10: 63.989255 | FE10: 28.04346 | FF10: 113.47803 | FG10: 0 | FH10: 5.0459 | FI10: 200.36719 | FJ10: 5.612305 | FK10: 10.09277 | FL10: 18.793455 | FM10: 14.74414 | FN10: 154.71582 | FO10: 66.97168 | FP10: 7524.9536 | FQ10: 594.2158 | FR10: 4226.0625 | FS10: 1050.6587 | FT10: 115.18604 | FU10: 1261.6123 | FV10: 1099.6988 | FW10: 827.04443 | FX10: 0 | FY10: 2736.4326 | FZ10: 0 | GA10: 0 | GB10: 2188.207 | GC10: 0 | GD10: 1771.4946 | GE10: 0 | GF10: 0 | GG10: 4772.6025 | GH10: 0 | GI10: 176.64356 | GJ10: 0 | GK10: 0 | GL10: 0 | GM10: 11.194825 | GN10: 0 | GO10: 223.24414 | GP10: 986.83836 | GQ10: 36.86865 | GR10: 1.27978 | GS10: 173.46533 | GT10: 49.605955 | GU10: 0 | GV10: 0 | GW10: 445.15284 | GX10: 0 | GY10: 0 | GZ10: 323.87354 | HA10: 0 | HB10: 539.74854 | HC10: 0 | HD10: 0 | HE10: 2729.2441 | HF10: 0 | HG10: 0 | HH10: 0 | HI10: 0 | HJ10: 0 | HK10: 6.92969 | HL10: 0 | HM10: 6.94482 | HN10: 1332.0298 | HO10: 134.30665 | HP10: 25.163085 | HQ10: 178.15918 | HR10: 172.31201 | HS10: 621.43358 | HT10: 0 | HU10: 795.96044 | HV10: 33.12353 | HW10: 0 | HX10: 777.55174 | HY10: 32.176765 | HZ10: 56.152835 | IA10: 0 | IB10: 0 | IC10: 6327.9639 | ID10: 0 | IE10: 101.24512 | IF10: 122.06055 | IG10: 0 | IH10: 138.94776 | II10: 8.49707 | IJ10: 402.45117 | IK10: 84.18457 | IL10: 135.87939 | IM10: 11.96045 | IN10: 5.182125 | IO10: 3.574705 | IP10: 5.39355 | IQ10: 39.99268 | IR10: 0 | IS10: 43.901855 | IT10: 10.04541 | IU10: 0 | IV10: 32.72705 | IW10: 0 | IX10: 32.458495 | IY10: 0 | IZ10: 0 | JA10: 6309.3883 | JB10: 0 | JC10: 0 | JD10: 6.44873 | JE10: 0 | JF10: 17.33887 | JG10: 7.025875 | JH10: 7.629885 | JI10: 12.149905 | JJ10: 982.9668 | JK10: 179.35791 | JL10: 225.97314 | JM10: 319.6377 | JN10: 305.25293 | JO10: 283.9043 | JP10: 0 | JQ10: 506.82324 | JR10: 366.35987 | JS10: 0 | JT10: 538.47851 | JU10: 198.8208 | JV10: 300.82567 | JW10: 0 | JX10: 84.610835 | JY10: 4527.5664 | JZ10: 0 | KA10: 75.71533 | KB10: 151.8955 | KC10: 35.29785 | KD10: 127.71973 | KE10: 86.623535 | KF10: 7898.6915 | KG10: 493.24023 | KH10: 0 | KI10: 864 | KJ10: 2632.25 | KK10: 4388 | KL10: 4111.25 | KM10: 929 | KN10: 118 | KO10: 7517.25 | KP10: 2942.75 | KQ10: 7663 | KR10: 688 | KS10: 1275.75 | KT10: 133456.25 | KU10: 0 | KV10: 0 | KW10: 15141.25 | KX10: 3970.5 | KY10: 1251.5 | KZ10: 521.75 | LA10: 0 | LB10: 0 | LC10: 0 | LD10: 0 | LE10: 19465.75 | LF10: 0 | LG10: 3862.3801 | LH10: 358.81456 | LI10: 296.86233 | LJ10: 0 | LK10: 0
A11: CC0054 | B11: 227704 | C11: 1.8571429 | D11: 1 | E11: 5 | F11: 247.50489 | G11: 372.09619 | H11: 368.22852 | I11: 255.26464 | J11: 272.1333 | K11: 344.18408 | L11: 379.0249 | M11: 836.95312 | N11: 393.6079 | O11: 377.31543 | P11: 508.02197 | Q11: 515.75976 | R11: 557.15528 | S11: 39.361325 | T11: 286.8916 | U11: 690.85255 | V11: 417.76806 | W11: 572.13379 | X11: 454.66308 | Y11: 339.31202 | Z11: 410.54688 | AA11: 756.73632 | AB11: 987.4458 | AC11: 401.68994 | AD11: 19.37256 | AE11: 5.02539 | AF11: 0.908695 | AG11: 2.13965 | AH11: 3.359375 | AI11: 7.58301 | AJ11: 2.50537 | AK11: 4.53467 | AL11: 6.92041 | AM11: 15.20459 | AN11: 9.515625 | AO11: 0 | AP11: 20.52002 | AQ11: 0 | AR11: 0 | AS11: 21.566405 | AT11: 9.34863 | AU11: 0 | AV11: 4.75147 | AW11: 0 | AX11: 50.26709 | AY11: 9.07617 | AZ11: 61.035645 | BA11: 9.857425 | BB11: 3.12207 | BC11: 1.433105 | BD11: 6.296875 | BE11: 0 | BF11: 0 | BG11: 6.30371 | BH11: 0 | BI11: 5.603515 | BJ11: 1.12158 | BK11: 0.53125 | BL11: 3.49756 | BM11: 0 | BN11: 18.409665 | BO11: 0 | BP11: 10.70899 | BQ11: 14.135745 | BR11: 0 | BS11: 0 | BT11: 12.208005 | BU11: 5.811525 | BV11: 6.922365 | BW11: 4.46338 | BX11: 11.745605 | BY11: 4.05273 | BZ11: 7.671385 | CA11: 3.186525 | CB11: 1.012695 | CC11: 0 | CD11: 1.50927 | CE11: 5.614745 | CF11: 1.62842 | CG11: 2.676755 | CH11: 7.40039 | CI11: 16.360355 | CJ11: 2.886715 | CK11: 0 | CL11: 18.208985 | CM11: 0 | CN11: 0 | CO11: 2.364255 | CP11: 2.67334 | CQ11: 0 | CR11: 0.512695 | CS11: 0 | CT11: 9.76026 | CU11: 10.440425 | CV11: 13.600095 | CW11: 8.768555 | CX11: 0 | CY11: 0 | CZ11: 1.304205 | DA11: 0 | DB11: 0 | DC11: 3.828125 | DD11: 0 | DE11: 0 | DF11: 4.71582 | DG11: 2.97168 | DH11: 2.259285 | DI11: 3.958005 | DJ11: 11.23242 | DK11: 0 | DL11: 4.952635 | DM11: 7.924315 | DN11: 3.52832 | DO11: 0 | DP11: 8.943845 | DQ11: 7.851565 | DR11: 6.716305 | DS11: 0 | DT11: 2.146 | DU11: 1.174805 | DV11: 639.41749 | DW11: 267.95263 | DX11: 69.13574 | DY11: 1091.6138 | DZ11: 1033.9736 | EA11: 256.00146 | EB11: 436.50244 | EC11: 946.86523 | ED11: 59.979005 | EE11: 2499.9936 | EF11: 1115.6303 | EG11: 366.90918 | EH11: 737.26123 | EI11: 2.9834 | EJ11: 64.104 | EK11: 768.76514 | EL11: 136.20752 | EM11: 545.05077 | EN11: 160.03711 | EO11: 4.711425 | EP11: 41.689455 | EQ11: 203.16748 | ER11: 1679.709 | ES11: 1161.0411 | ET11: 113.62842 | EU11: 23.340815 | EV11: 7.05371 | EW11: 266.17725 | EX11: 260.6997 | EY11: 24.80517 | EZ11: 4.350585 | FA11: 149.01318 | FB11: 7.015625 | FC11: 806.8345 | FD11: 152.61524 | FE11: 25.321295 | FF11: 180.34716 | FG11: 0 | FH11: 1.83203 | FI11: 138.09375 | FJ11: 0 | FK11: 32.31885 | FL11: 11.048825 | FM11: 0 | FN11: 27.43066 | FO11: 57.59912 | FP11: 384.08691 | FQ11: 298.45214 | FR11: 10639.472 | FS11: 8249.9248 | FT11: 2625.5352 | FU11: 7489.8138 | FV11: 7032.567 | FW11: 4086.2394 | FX11: 1721.6287 | FY11: 1573.4873 | FZ11: 0 | GA11: 0 | GB11: 2151.4204 | GC11: 0 | GD11: 1459.4345 | GE11: 0 | GF11: 0 | GG11: 3410.0518 | GH11: 682.94175 | GI11: 5264.673 | GJ11: 5811.1303 | GK11: 0 | GL11: 22.338865 | GM11: 20.06787 | GN11: 9847.7815 | GO11: 2972.7925 | GP11: 7407.1641 | GQ11: 4359.021 | GR11: 251.7539 | GS11: 3177.0767 | GT11: 3066.646 | GU11: 1377.7725 | GV11: 0 | GW11: 90.15137 | GX11: 0 | GY11: 0 | GZ11: 275.81007 | HA11: 0 | HB11: 328.56297 | HC11: 0 | HD11: 0 | HE11: 2156.8783 | HF11: 831.12549 | HG11: 1987.2417 | HH11: 2541.6172 | HI11: 0 | HJ11: 0 | HK11: 8.676755 | HL11: 8542.7161 | HM11: 653.09278 | HN11: 3511.1069 | HO11: 2036.5552 | HP11: 296.67383 | HQ11: 1311.3267 | HR11: 1324.0029 | HS11: 1007.7544 | HT11: 0 | HU11: 229.77784 | HV11: 9.05176 | HW11: 0 | HX11: 346.76855 | HY11: 21.52588 | HZ11: 56.330565 | IA11: 13.915045 | IB11: 0 | IC11: 3416.5444 | ID11: 0 | IE11: 1154.4424 | IF11: 1787.1978 | IG11: 0 | IH11: 28.72998 | II11: 9.527835 | IJ11: 4625.7413 | IK11: 1387.8609 | IL11: 3386.0107 | IM11: 1713.417 | IN11: 62.60986 | IO11: 455.89209 | IP11: 435.79638 | IQ11: 211.88331 | IR11: 0 | IS11: 12.96631 | IT11: 8.59082 | IU11: 0 | IV11: 35.071285 | IW11: 0 | IX11: 28.967775 | IY11: 0 | IZ11: 0 | JA11: 3871.2724 | JB11: 0 | JC11: 712.57957 | JD11: 1175.9018 | JE11: 0 | JF11: 18.487795 | JG11: 8.896485 | JH11: 5447.2696 | JI11: 1546.395 | JJ11: 438.43164 | JK11: 112.97461 | JL11: 21.874995 | JM11: 349.14355 | JN11: 319.62109 | JO11: 169.14942 | JP11: 0 | JQ11: 651.4961 | JR11: 0 | JS11: 0 | JT11: 813.708 | JU11: 147.74267 | JV11: 387.67579 | JW11: 0 | JX11: 0 | JY11: 1046.4077 | JZ11: 0 | KA11: 507.61278 | KB11: 107.33935 | KC11: 0 | KD11: 17.50195 | KE11: 46.00244 | KF11: 1056.313 | KG11: 931.3921 | KH11: 0 | KI11: 0 | KJ11: 556.75 | KK11: 736.75 | KL11: 1416 | KM11: 0 | KN11: 0 | KO11: 6000.5 | KP11: 0 | KQ11: 5913 | KR11: 0 | KS11: 773.75 | KT11: 251460.5 | KU11: 0 | KV11: 0 | KW11: 13506.75 | KX11: 1509.5 | KY11: 0 | KZ11: 0 | LA11: 0 | LB11: 0 | LC11: 0 | LD11: 0 | LE11: 17926.75 | LF11: 825.17734 | LG11: 3024.1392 | LH11: 54.28088 | LI11: 431.61625 | LJ11: 101.90434 | LK11: 0
